Workbook

Sheet 01
A1: 中和郵局 抽測國內快捷情形報告單
G2: 115年 | H2: 1月
A3: 互寄地區 | C3: 抽測件數 | D3: J+2時 件數 | E3: J+2時 投遞率 | F3: J+4時 件數 | G3: J+4時 投遞率 | H3: J+6時 件數 | I3: J+6時 投遞率 | J3: J+8時 件數 | K3: J+8時 投遞率 | L3: 8時以上 件數 | M3: 8時以上 投遞率 | N3: 符合時效比例 | O3: 平均 (時)數
A4: 本收本投 | C4: =D4+F4+H4+J4+L4 -> 0 | D4: =COUNTIF(01子本!$E$3:$E$17,"J+2") -> 0 | E4: =IF($C4=0,"",D4/$C4) | F4: =COUNTIF(01子本!$E$3:$E$17,"J+4") -> 0 | G4: =IF($C4=0,"",F4/$C4) | H4: =COUNTIF(01子本!$E$3:$E$17,"J+6") -> 0 | I4: =IF($C4=0,"",H4/$C4) | J4: =COUNTIF(01子本!$E$3:$E$17,"J+8") -> 0 | K4: =IF($C4=0,"",J4/$C4) | L4: =COUNTIF(01子本!$E$3:$E$17,"8以上") -> 0 | M4: =IF($C4=0,"",L4/$C4) | N4: 1 | O4: =IF($C4=0,"",(D4*2+F4*4+H4*6+J4*8+L4*8)/$C4)
A5: 主要都市間互寄 | C5: =D5+F5+H5+J5+L5 -> 0 | D5: =COUNTIF(01子本!$E$23:$E$37,"J+2") -> 0 | E5: =IF($C5=0,"",D5/$C5) | F5: =COUNTIF(01子本!$E$23:$E$37,"J+4") -> 0 | G5: =IF($C5=0,"",F5/$C5) | H5: =COUNTIF(01子本!$E$23:$E$37,"J+6") -> 0 | I5: =IF($C5=0,"",H5/$C5) | J5: =COUNTIF(01子本!$E$23:$E$37,"J+8") -> 0 | K5: =IF($C5=0,"",J5/$C5) | L5: =COUNTIF(01子本!$E$23:$E$37,"8以上") -> 0 | M5: =IF($C5=0,"",L5/$C5) | N5: 1 | O5: =IF($C5=0,"",(D5*2+F5*4+H5*6+J5*8+L5*8)/$C5)
A6: 區域內互寄 (北北基、台中、高雄、中彰投地區) | C6: =D6+F6+H6+J6+L6 -> 0 | D6: =COUNTIF(01子本!$E$43:$E$57,"J+2") -> 0 | E6: =IF($C6=0,"",D6/$C6) | F6: =COUNTIF(01子本!$E$43:$E$57,"J+4") -> 0 | G6: =IF($C6=0,"",F6/$C6) | H6: =COUNTIF(01子本!$E$43:$E$57,"J+6") -> 0 | I6: =IF($C6=0,"",H6/$C6) | J6: =COUNTIF(01子本!$E$43:$E$57,"J+8") -> 0 | K6: =IF($C6=0,"",J6/$C6) | L6: =COUNTIF(01子本!$E$43:$E$57,"8以上") -> 0 | M6: =IF($C6=0,"",L6/$C6) | N6: 1 | O6: =IF($C6=0,"",(D6*2+F6*4+H6*6+J6*8+L6*8)/$C6)
A7: 其他轉口 | C7: =D7+F7+H7+J7+L7 -> 0 | D7: =COUNTIF(01子本!$E$63:$E$77,"J+2") -> 0 | E7: =IF($C7=0,"",D7/$C7) | F7: =COUNTIF(01子本!$E$63:$E$77,"J+4") -> 0 | G7: =IF($C7=0,"",F7/$C7) | H7: =COUNTIF(01子本!$E$63:$E$77,"J+6") -> 0 | I7: =IF($C7=0,"",H7/$C7) | J7: =COUNTIF(01子本!$E$63:$E$77,"J+8") -> 0 | K7: =IF($C7=0,"",J7/$C7) | L7: =COUNTIF(01子本!$E$63:$E$77,"8以上") -> 0 | M7: =IF($C7=0,"",L7/$C7) | N7: 1 | O7: =IF($C7=0,"",(D7*2+F7*4+H7*6+J7*8+L7*8)/$C7)
A8: 說明：
A9: 1 | B9: 為瞭解國內快捷郵件寄遞時效，各局快捷單位應透過MQ或本公司全球資訊網查詢系統抽測「本收本投」、「主要都市互寄」、「區域內互寄」、「其他轉口」4類，每月至少各10件（抽查紀錄列印或記錄郵件號碼留局備查，保存1年），抽測結果於次月5日前寄管轄郵局郵務科彙整，於8日前上傳主機。
A10: 2 | B10: 抽測樣本：本收本投以15時前交寄、主要都市互寄11時前交寄、區域間互寄13時前交寄之郵件抽測為主。
A11: 3 | B11: 寄遞時效：自「交寄郵件」到「郵件投遞中」之處理狀態時間計算，四小時以內者填「ｊ＋4時」欄；逾四小時不逾六小時者填「ｊ＋6時」欄，餘類推。抽測結果有不符合時效標準者，請將相關地名列出，並檢討改善。
A12: 4 | B12: 十大都市互寄係指台北市(100-110)、板橋市(220)、桃園市(330)、中壢市(含平鎮，320、324)、新竹市(300)、台中市(400-408)、彰化市(500)、嘉義市(600)、台南市(700-709)、高雄市(800-804、806、807)互寄者。該欄位僅由該十大都市互寄局就相關之郵件抽測情形填註。
A13: 5 | B13: 平均(時)數：((J+2小時投遞率)*2+(J+4小時投遞率)*4+(J+6小時投遞率)*6+(J+8小時投遞率)*8+(J+8小時以上投遞率)*8)/100。
B14: 製表: | F14: 主管:

Sheet 01子本
A1: ="中和郵務股"&'01'!$G$2&'01'!$H$2&"份 本口 快捷郵遞時效表" -> 中和郵務股115年1月份 本口 快捷郵遞時效表
A2: 郵件號碼 | B2: 交寄時間 | C2: 交投時間 | D2: 時數 | E2: 時效
D3: =IF(OR(B3="",C3=""),"",ROUND((IF(C3<1,INT(B3)+C3,C3)-B3)*1440,0)/1440) | E3: =IF(D3="","",IF(D3<0,"打日期",IF(D3*1440<=120,"J+2",IF(D3*1440<=240,"J+4",IF(D3*1440<=360,"J+6",IF(D3*1440<=480,"J+8","8以上"))))))
D4: =IF(OR(B4="",C4=""),"",ROUND((IF(C4<1,INT(B4)+C4,C4)-B4)*1440,0)/1440) | E4: =IF(D4="","",IF(D4<0,"打日期",IF(D4*1440<=120,"J+2",IF(D4*1440<=240,"J+4",IF(D4*1440<=360,"J+6",IF(D4*1440<=480,"J+8","8以上"))))))
D5: =IF(OR(B5="",C5=""),"",ROUND((IF(C5<1,INT(B5)+C5,C5)-B5)*1440,0)/1440) | E5: =IF(D5="","",IF(D5<0,"打日期",IF(D5*1440<=120,"J+2",IF(D5*1440<=240,"J+4",IF(D5*1440<=360,"J+6",IF(D5*1440<=480,"J+8","8以上"))))))
D6: =IF(OR(B6="",C6=""),"",ROUND((IF(C6<1,INT(B6)+C6,C6)-B6)*1440,0)/1440) | E6: =IF(D6="","",IF(D6<0,"打日期",IF(D6*1440<=120,"J+2",IF(D6*1440<=240,"J+4",IF(D6*1440<=360,"J+6",IF(D6*1440<=480,"J+8","8以上"))))))
D7: =IF(OR(B7="",C7=""),"",ROUND((IF(C7<1,INT(B7)+C7,C7)-B7)*1440,0)/1440) | E7: =IF(D7="","",IF(D7<0,"打日期",IF(D7*1440<=120,"J+2",IF(D7*1440<=240,"J+4",IF(D7*1440<=360,"J+6",IF(D7*1440<=480,"J+8","8以上"))))))
D8: =IF(OR(B8="",C8=""),"",ROUND((IF(C8<1,INT(B8)+C8,C8)-B8)*1440,0)/1440) | E8: =IF(D8="","",IF(D8<0,"打日期",IF(D8*1440<=120,"J+2",IF(D8*1440<=240,"J+4",IF(D8*1440<=360,"J+6",IF(D8*1440<=480,"J+8","8以上"))))))
D9: =IF(OR(B9="",C9=""),"",ROUND((IF(C9<1,INT(B9)+C9,C9)-B9)*1440,0)/1440) | E9: =IF(D9="","",IF(D9<0,"打日期",IF(D9*1440<=120,"J+2",IF(D9*1440<=240,"J+4",IF(D9*1440<=360,"J+6",IF(D9*1440<=480,"J+8","8以上"))))))
D10: =IF(OR(B10="",C10=""),"",ROUND((IF(C10<1,INT(B10)+C10,C10)-B10)*1440,0)/1440) | E10: =IF(D10="","",IF(D10<0,"打日期",IF(D10*1440<=120,"J+2",IF(D10*1440<=240,"J+4",IF(D10*1440<=360,"J+6",IF(D10*1440<=480,"J+8","8以上"))))))
D11: =IF(OR(B11="",C11=""),"",ROUND((IF(C11<1,INT(B11)+C11,C11)-B11)*1440,0)/1440) | E11: =IF(D11="","",IF(D11<0,"打日期",IF(D11*1440<=120,"J+2",IF(D11*1440<=240,"J+4",IF(D11*1440<=360,"J+6",IF(D11*1440<=480,"J+8","8以上"))))))
D12: =IF(OR(B12="",C12=""),"",ROUND((IF(C12<1,INT(B12)+C12,C12)-B12)*1440,0)/1440) | E12: =IF(D12="","",IF(D12<0,"打日期",IF(D12*1440<=120,"J+2",IF(D12*1440<=240,"J+4",IF(D12*1440<=360,"J+6",IF(D12*1440<=480,"J+8","8以上"))))))
D13: =IF(OR(B13="",C13=""),"",ROUND((IF(C13<1,INT(B13)+C13,C13)-B13)*1440,0)/1440) | E13: =IF(D13="","",IF(D13<0,"打日期",IF(D13*1440<=120,"J+2",IF(D13*1440<=240,"J+4",IF(D13*1440<=360,"J+6",IF(D13*1440<=480,"J+8","8以上"))))))
D14: =IF(OR(B14="",C14=""),"",ROUND((IF(C14<1,INT(B14)+C14,C14)-B14)*1440,0)/1440) | E14: =IF(D14="","",IF(D14<0,"打日期",IF(D14*1440<=120,"J+2",IF(D14*1440<=240,"J+4",IF(D14*1440<=360,"J+6",IF(D14*1440<=480,"J+8","8以上"))))))
... D17: =IF(OR(B17="",C17=""),"",ROUND((IF(C17<1,INT(B17)+C17,C17)-B17)*1440,0)/1440) | E17: =IF(D17="","",IF(D17<0,"打日期",IF(D17*1440<=120,"J+2",IF(D17*1440<=240,"J+4",IF(D17*1440<=360,"J+6",IF(D17*1440<=480,"J+8","8以上"))))))
A18: 本地互寄:( 15時前交寄之郵件) 板橋市22071~81、92
A20: 製表: | C20: 主管:
A21: ="中和郵務股"&'01'!$G$2&'01'!$H$2&"份 十大都會區 快捷郵遞時效表" -> 中和郵務股115年1月份 十大都會區 快捷郵遞時效表
A22: 郵件號碼 | B22: 交寄時間 | C22: 交投時間 | D22: 時數 | E22: 時效
D23: =IF(OR(B23="",C23=""),"",ROUND((IF(C23<1,INT(B23)+C23,C23)-B23)*1440,0)/1440) | E23: =IF(D23="","",IF(D23<0,"打日期",IF(D23*1440<=120,"J+2",IF(D23*1440<=240,"J+4",IF(D23*1440<=360,"J+6",IF(D23*1440<=480,"J+8","8以上"))))))
D24: =IF(OR(B24="",C24=""),"",ROUND((IF(C24<1,INT(B24)+C24,C24)-B24)*1440,0)/1440) | E24: =IF(D24="","",IF(D24<0,"打日期",IF(D24*1440<=120,"J+2",IF(D24*1440<=240,"J+4",IF(D24*1440<=360,"J+6",IF(D24*1440<=480,"J+8","8以上"))))))
D25: =IF(OR(B25="",C25=""),"",ROUND((IF(C25<1,INT(B25)+C25,C25)-B25)*1440,0)/1440) | E25: =IF(D25="","",IF(D25<0,"打日期",IF(D25*1440<=120,"J+2",IF(D25*1440<=240,"J+4",IF(D25*1440<=360,"J+6",IF(D25*1440<=480,"J+8","8以上"))))))
D26: =IF(OR(B26="",C26=""),"",ROUND((IF(C26<1,INT(B26)+C26,C26)-B26)*1440,0)/1440) | E26: =IF(D26="","",IF(D26<0,"打日期",IF(D26*1440<=120,"J+2",IF(D26*1440<=240,"J+4",IF(D26*1440<=360,"J+6",IF(D26*1440<=480,"J+8","8以上"))))))
D27: =IF(OR(B27="",C27=""),"",ROUND((IF(C27<1,INT(B27)+C27,C27)-B27)*1440,0)/1440) | E27: =IF(D27="","",IF(D27<0,"打日期",IF(D27*1440<=120,"J+2",IF(D27*1440<=240,"J+4",IF(D27*1440<=360,"J+6",IF(D27*1440<=480,"J+8","8以上"))))))
D28: =IF(OR(B28="",C28=""),"",ROUND((IF(C28<1,INT(B28)+C28,C28)-B28)*1440,0)/1440) | E28: =IF(D28="","",IF(D28<0,"打日期",IF(D28*1440<=120,"J+2",IF(D28*1440<=240,"J+4",IF(D28*1440<=360,"J+6",IF(D28*1440<=480,"J+8","8以上"))))))
D29: =IF(OR(B29="",C29=""),"",ROUND((IF(C29<1,INT(B29)+C29,C29)-B29)*1440,0)/1440) | E29: =IF(D29="","",IF(D29<0,"打日期",IF(D29*1440<=120,"J+2",IF(D29*1440<=240,"J+4",IF(D29*1440<=360,"J+6",IF(D29*1440<=480,"J+8","8以上"))))))
D30: =IF(OR(B30="",C30=""),"",ROUND((IF(C30<1,INT(B30)+C30,C30)-B30)*1440,0)/1440) | E30: =IF(D30="","",IF(D30<0,"打日期",IF(D30*1440<=120,"J+2",IF(D30*1440<=240,"J+4",IF(D30*1440<=360,"J+6",IF(D30*1440<=480,"J+8","8以上"))))))
D31: =IF(OR(B31="",C31=""),"",ROUND((IF(C31<1,INT(B31)+C31,C31)-B31)*1440,0)/1440) | E31: =IF(D31="","",IF(D31<0,"打日期",IF(D31*1440<=120,"J+2",IF(D31*1440<=240,"J+4",IF(D31*1440<=360,"J+6",IF(D31*1440<=480,"J+8","8以上"))))))
D32: =IF(OR(B32="",C32=""),"",ROUND((IF(C32<1,INT(B32)+C32,C32)-B32)*1440,0)/1440) | E32: =IF(D32="","",IF(D32<0,"打日期",IF(D32*1440<=120,"J+2",IF(D32*1440<=240,"J+4",IF(D32*1440<=360,"J+6",IF(D32*1440<=480,"J+8","8以上"))))))
D33: =IF(OR(B33="",C33=""),"",ROUND((IF(C33<1,INT(B33)+C33,C33)-B33)*1440,0)/1440) | E33: =IF(D33="","",IF(D33<0,"打日期",IF(D33*1440<=120,"J+2",IF(D33*1440<=240,"J+4",IF(D33*1440<=360,"J+6",IF(D33*1440<=480,"J+8","8以上"))))))
D34: =IF(OR(B34="",C34=""),"",ROUND((IF(C34<1,INT(B34)+C34,C34)-B34)*1440,0)/1440) | E34: =IF(D34="","",IF(D34<0,"打日期",IF(D34*1440<=120,"J+2",IF(D34*1440<=240,"J+4",IF(D34*1440<=360,"J+6",IF(D34*1440<=480,"J+8","8以上"))))))
... D37: =IF(OR(B37="",C37=""),"",ROUND((IF(C37<1,INT(B37)+C37,C37)-B37)*1440,0)/1440) | E37: =IF(D37="","",IF(D37<0,"打日期",IF(D37*1440<=120,"J+2",IF(D37*1440<=240,"J+4",IF(D37*1440<=360,"J+6",IF(D37*1440<=480,"J+8","8以上"))))))
A38: 十大都市:( 11時前交寄之郵件) 台北市(100-110)、基隆市(200~206)、桃園市(330)、中壢市(含平鎮，320、324)、台中市(400-408)、彰化市(500)、嘉義市(600)、台南市(700-709)、高雄市(800-804、806、807)互寄者。
A40: 製表: | C40: 主管:
A41: ="中和郵務股"&'01'!$G$2&'01'!$H$2&"份 區域內互寄 快捷郵遞時效表" -> 中和郵務股115年1月份 區域內互寄 快捷郵遞時效表
A42: 郵件號碼 | B42: 交寄時間 | C42: 交投時間 | D42: 時數 | E42: 時效
D43: =IF(OR(B43="",C43=""),"",ROUND((IF(C43<1,INT(B43)+C43,C43)-B43)*1440,0)/1440) | E43: =IF(D43="","",IF(D43<0,"打日期",IF(D43*1440<=120,"J+2",IF(D43*1440<=240,"J+4",IF(D43*1440<=360,"J+6",IF(D43*1440<=480,"J+8","8以上"))))))
D44: =IF(OR(B44="",C44=""),"",ROUND((IF(C44<1,INT(B44)+C44,C44)-B44)*1440,0)/1440) | E44: =IF(D44="","",IF(D44<0,"打日期",IF(D44*1440<=120,"J+2",IF(D44*1440<=240,"J+4",IF(D44*1440<=360,"J+6",IF(D44*1440<=480,"J+8","8以上"))))))
D45: =IF(OR(B45="",C45=""),"",ROUND((IF(C45<1,INT(B45)+C45,C45)-B45)*1440,0)/1440) | E45: =IF(D45="","",IF(D45<0,"打日期",IF(D45*1440<=120,"J+2",IF(D45*1440<=240,"J+4",IF(D45*1440<=360,"J+6",IF(D45*1440<=480,"J+8","8以上"))))))
D46: =IF(OR(B46="",C46=""),"",ROUND((IF(C46<1,INT(B46)+C46,C46)-B46)*1440,0)/1440) | E46: =IF(D46="","",IF(D46<0,"打日期",IF(D46*1440<=120,"J+2",IF(D46*1440<=240,"J+4",IF(D46*1440<=360,"J+6",IF(D46*1440<=480,"J+8","8以上"))))))
...

Sheet 02
A1: 中和郵局 抽測國內快捷情形報告單
G2: ='01'!G2 -> 115年 | H2: 2月
A3: 互寄地區 | C3: 抽測件數 | D3: J+2時 件數 | E3: J+2時 投遞率 | F3: J+4時 件數 | G3: J+4時 投遞率 | H3: J+6時 件數 | I3: J+6時 投遞率 | J3: J+8時 件數 | K3: J+8時 投遞率 | L3: 8時以上 件數 | M3: 8時以上 投遞率 | N3: 符合時效比例 | O3: 平均 (時)數
A4: 本收本投 | C4: =D4+F4+H4+J4+L4 -> 0 | D4: =COUNTIF(02子本!$E$3:$E$17,"J+2") -> 0 | E4: =IF($C4=0,"",D4/$C4) | F4: =COUNTIF(02子本!$E$3:$E$17,"J+4") -> 0 | G4: =IF($C4=0,"",F4/$C4) | H4: =COUNTIF(02子本!$E$3:$E$17,"J+6") -> 0 | I4: =IF($C4=0,"",H4/$C4) | J4: =COUNTIF(02子本!$E$3:$E$17,"J+8") -> 0 | K4: =IF($C4=0,"",J4/$C4) | L4: =COUNTIF(02子本!$E$3:$E$17,"8以上") -> 0 | M4: =IF($C4=0,"",L4/$C4) | N4: 1 | O4: =IF($C4=0,"",(D4*2+F4*4+H4*6+J4*8+L4*8)/$C4)
A5: 主要都市間互寄 | C5: =D5+F5+H5+J5+L5 -> 0 | D5: =COUNTIF(02子本!$E$23:$E$37,"J+2") -> 0 | E5: =IF($C5=0,"",D5/$C5) | F5: =COUNTIF(02子本!$E$23:$E$37,"J+4") -> 0 | G5: =IF($C5=0,"",F5/$C5) | H5: =COUNTIF(02子本!$E$23:$E$37,"J+6") -> 0 | I5: =IF($C5=0,"",H5/$C5) | J5: =COUNTIF(02子本!$E$23:$E$37,"J+8") -> 0 | K5: =IF($C5=0,"",J5/$C5) | L5: =COUNTIF(02子本!$E$23:$E$37,"8以上") -> 0 | M5: =IF($C5=0,"",L5/$C5) | N5: 1 | O5: =IF($C5=0,"",(D5*2+F5*4+H5*6+J5*8+L5*8)/$C5)
A6: 區域內互寄 (北北基、台中、高雄、中彰投地區) | C6: =D6+F6+H6+J6+L6 -> 0 | D6: =COUNTIF(02子本!$E$43:$E$57,"J+2") -> 0 | E6: =IF($C6=0,"",D6/$C6) | F6: =COUNTIF(02子本!$E$43:$E$57,"J+4") -> 0 | G6: =IF($C6=0,"",F6/$C6) | H6: =COUNTIF(02子本!$E$43:$E$57,"J+6") -> 0 | I6: =IF($C6=0,"",H6/$C6) | J6: =COUNTIF(02子本!$E$43:$E$57,"J+8") -> 0 | K6: =IF($C6=0,"",J6/$C6) | L6: =COUNTIF(02子本!$E$43:$E$57,"8以上") -> 0 | M6: =IF($C6=0,"",L6/$C6) | N6: 1 | O6: =IF($C6=0,"",(D6*2+F6*4+H6*6+J6*8+L6*8)/$C6)
A7: 其他轉口 | C7: =D7+F7+H7+J7+L7 -> 0 | D7: =COUNTIF(02子本!$E$63:$E$77,"J+2") -> 0 | E7: =IF($C7=0,"",D7/$C7) | F7: =COUNTIF(02子本!$E$63:$E$77,"J+4") -> 0 | G7: =IF($C7=0,"",F7/$C7) | H7: =COUNTIF(02子本!$E$63:$E$77,"J+6") -> 0 | I7: =IF($C7=0,"",H7/$C7) | J7: =COUNTIF(02子本!$E$63:$E$77,"J+8") -> 0 | K7: =IF($C7=0,"",J7/$C7) | L7: =COUNTIF(02子本!$E$63:$E$77,"8以上") -> 0 | M7: =IF($C7=0,"",L7/$C7) | N7: 1 | O7: =IF($C7=0,"",(D7*2+F7*4+H7*6+J7*8+L7*8)/$C7)
A8: 說明：
A9: 1 | B9: 為瞭解國內快捷郵件寄遞時效，各局快捷單位應透過MQ或本公司全球資訊網查詢系統抽測「本收本投」、「主要都市互寄」、「區域內互寄」、「其他轉口」4類，每月至少各10件（抽查紀錄列印或記錄郵件號碼留局備查，保存1年），抽測結果於次月5日前寄管轄郵局郵務科彙整，於8日前上傳主機。
A10: 2 | B10: 抽測樣本：本收本投以15時前交寄、主要都市互寄11時前交寄、區域間互寄13時前交寄之郵件抽測為主。
A11: 3 | B11: 寄遞時效：自「交寄郵件」到「郵件投遞中」之處理狀態時間計算，四小時以內者填「ｊ＋4時」欄；逾四小時不逾六小時者填「ｊ＋6時」欄，餘類推。抽測結果有不符合時效標準者，請將相關地名列出，並檢討改善。
A12: 4 | B12: 十大都市互寄係指台北市(100-110)、板橋市(220)、桃園市(330)、中壢市(含平鎮，320、324)、新竹市(300)、台中市(400-408)、彰化市(500)、嘉義市(600)、台南市(700-709)、高雄市(800-804、806、807)互寄者。該欄位僅由該十大都市互寄局就相關之郵件抽測情形填註。
A13: 5 | B13: 平均(時)數：((J+2小時投遞率)*2+(J+4小時投遞率)*4+(J+6小時投遞率)*6+(J+8小時投遞率)*8+(J+8小時以上投遞率)*8)/100。
B14: 製表: | F14: 主管:

Sheet 02子本
A1: ="中和郵務股"&'02'!$G$2&'02'!$H$2&"份 本口 快捷郵遞時效表" -> 中和郵務股115年2月份 本口 快捷郵遞時效表
A2: 郵件號碼 | B2: 交寄時間 | C2: 交投時間 | D2: 時數 | E2: 時效
D3: =IF(OR(B3="",C3=""),"",ROUND((IF(C3<1,INT(B3)+C3,C3)-B3)*1440,0)/1440) | E3: =IF(D3="","",IF(D3<0,"打日期",IF(D3*1440<=120,"J+2",IF(D3*1440<=240,"J+4",IF(D3*1440<=360,"J+6",IF(D3*1440<=480,"J+8","8以上"))))))
D4: =IF(OR(B4="",C4=""),"",ROUND((IF(C4<1,INT(B4)+C4,C4)-B4)*1440,0)/1440) | E4: =IF(D4="","",IF(D4<0,"打日期",IF(D4*1440<=120,"J+2",IF(D4*1440<=240,"J+4",IF(D4*1440<=360,"J+6",IF(D4*1440<=480,"J+8","8以上"))))))
D5: =IF(OR(B5="",C5=""),"",ROUND((IF(C5<1,INT(B5)+C5,C5)-B5)*1440,0)/1440) | E5: =IF(D5="","",IF(D5<0,"打日期",IF(D5*1440<=120,"J+2",IF(D5*1440<=240,"J+4",IF(D5*1440<=360,"J+6",IF(D5*1440<=480,"J+8","8以上"))))))
D6: =IF(OR(B6="",C6=""),"",ROUND((IF(C6<1,INT(B6)+C6,C6)-B6)*1440,0)/1440) | E6: =IF(D6="","",IF(D6<0,"打日期",IF(D6*1440<=120,"J+2",IF(D6*1440<=240,"J+4",IF(D6*1440<=360,"J+6",IF(D6*1440<=480,"J+8","8以上"))))))
D7: =IF(OR(B7="",C7=""),"",ROUND((IF(C7<1,INT(B7)+C7,C7)-B7)*1440,0)/1440) | E7: =IF(D7="","",IF(D7<0,"打日期",IF(D7*1440<=120,"J+2",IF(D7*1440<=240,"J+4",IF(D7*1440<=360,"J+6",IF(D7*1440<=480,"J+8","8以上"))))))
D8: =IF(OR(B8="",C8=""),"",ROUND((IF(C8<1,INT(B8)+C8,C8)-B8)*1440,0)/1440) | E8: =IF(D8="","",IF(D8<0,"打日期",IF(D8*1440<=120,"J+2",IF(D8*1440<=240,"J+4",IF(D8*1440<=360,"J+6",IF(D8*1440<=480,"J+8","8以上"))))))
D9: =IF(OR(B9="",C9=""),"",ROUND((IF(C9<1,INT(B9)+C9,C9)-B9)*1440,0)/1440) | E9: =IF(D9="","",IF(D9<0,"打日期",IF(D9*1440<=120,"J+2",IF(D9*1440<=240,"J+4",IF(D9*1440<=360,"J+6",IF(D9*1440<=480,"J+8","8以上"))))))
D10: =IF(OR(B10="",C10=""),"",ROUND((IF(C10<1,INT(B10)+C10,C10)-B10)*1440,0)/1440) | E10: =IF(D10="","",IF(D10<0,"打日期",IF(D10*1440<=120,"J+2",IF(D10*1440<=240,"J+4",IF(D10*1440<=360,"J+6",IF(D10*1440<=480,"J+8","8以上"))))))
D11: =IF(OR(B11="",C11=""),"",ROUND((IF(C11<1,INT(B11)+C11,C11)-B11)*1440,0)/1440) | E11: =IF(D11="","",IF(D11<0,"打日期",IF(D11*1440<=120,"J+2",IF(D11*1440<=240,"J+4",IF(D11*1440<=360,"J+6",IF(D11*1440<=480,"J+8","8以上"))))))
D12: =IF(OR(B12="",C12=""),"",ROUND((IF(C12<1,INT(B12)+C12,C12)-B12)*1440,0)/1440) | E12: =IF(D12="","",IF(D12<0,"打日期",IF(D12*1440<=120,"J+2",IF(D12*1440<=240,"J+4",IF(D12*1440<=360,"J+6",IF(D12*1440<=480,"J+8","8以上"))))))
D13: =IF(OR(B13="",C13=""),"",ROUND((IF(C13<1,INT(B13)+C13,C13)-B13)*1440,0)/1440) | E13: =IF(D13="","",IF(D13<0,"打日期",IF(D13*1440<=120,"J+2",IF(D13*1440<=240,"J+4",IF(D13*1440<=360,"J+6",IF(D13*1440<=480,"J+8","8以上"))))))
D14: =IF(OR(B14="",C14=""),"",ROUND((IF(C14<1,INT(B14)+C14,C14)-B14)*1440,0)/1440) | E14: =IF(D14="","",IF(D14<0,"打日期",IF(D14*1440<=120,"J+2",IF(D14*1440<=240,"J+4",IF(D14*1440<=360,"J+6",IF(D14*1440<=480,"J+8","8以上"))))))
... D17: =IF(OR(B17="",C17=""),"",ROUND((IF(C17<1,INT(B17)+C17,C17)-B17)*1440,0)/1440) | E17: =IF(D17="","",IF(D17<0,"打日期",IF(D17*1440<=120,"J+2",IF(D17*1440<=240,"J+4",IF(D17*1440<=360,"J+6",IF(D17*1440<=480,"J+8","8以上"))))))
A18: 本地互寄:( 15時前交寄之郵件) 板橋市22071~81、92
A20: 製表: | C20: 主管:
A21: ="中和郵務股"&'02'!$G$2&'02'!$H$2&"份 十大都會區 快捷郵遞時效表" -> 中和郵務股115年2月份 十大都會區 快捷郵遞時效表
A22: 郵件號碼 | B22: 交寄時間 | C22: 交投時間 | D22: 時數 | E22: 時效
D23: =IF(OR(B23="",C23=""),"",ROUND((IF(C23<1,INT(B23)+C23,C23)-B23)*1440,0)/1440) | E23: =IF(D23="","",IF(D23<0,"打日期",IF(D23*1440<=120,"J+2",IF(D23*1440<=240,"J+4",IF(D23*1440<=360,"J+6",IF(D23*1440<=480,"J+8","8以上"))))))
D24: =IF(OR(B24="",C24=""),"",ROUND((IF(C24<1,INT(B24)+C24,C24)-B24)*1440,0)/1440) | E24: =IF(D24="","",IF(D24<0,"打日期",IF(D24*1440<=120,"J+2",IF(D24*1440<=240,"J+4",IF(D24*1440<=360,"J+6",IF(D24*1440<=480,"J+8","8以上"))))))
D25: =IF(OR(B25="",C25=""),"",ROUND((IF(C25<1,INT(B25)+C25,C25)-B25)*1440,0)/1440) | E25: =IF(D25="","",IF(D25<0,"打日期",IF(D25*1440<=120,"J+2",IF(D25*1440<=240,"J+4",IF(D25*1440<=360,"J+6",IF(D25*1440<=480,"J+8","8以上"))))))
D26: =IF(OR(B26="",C26=""),"",ROUND((IF(C26<1,INT(B26)+C26,C26)-B26)*1440,0)/1440) | E26: =IF(D26="","",IF(D26<0,"打日期",IF(D26*1440<=120,"J+2",IF(D26*1440<=240,"J+4",IF(D26*1440<=360,"J+6",IF(D26*1440<=480,"J+8","8以上"))))))
D27: =IF(OR(B27="",C27=""),"",ROUND((IF(C27<1,INT(B27)+C27,C27)-B27)*1440,0)/1440) | E27: =IF(D27="","",IF(D27<0,"打日期",IF(D27*1440<=120,"J+2",IF(D27*1440<=240,"J+4",IF(D27*1440<=360,"J+6",IF(D27*1440<=480,"J+8","8以上"))))))
D28: =IF(OR(B28="",C28=""),"",ROUND((IF(C28<1,INT(B28)+C28,C28)-B28)*1440,0)/1440) | E28: =IF(D28="","",IF(D28<0,"打日期",IF(D28*1440<=120,"J+2",IF(D28*1440<=240,"J+4",IF(D28*1440<=360,"J+6",IF(D28*1440<=480,"J+8","8以上"))))))
D29: =IF(OR(B29="",C29=""),"",ROUND((IF(C29<1,INT(B29)+C29,C29)-B29)*1440,0)/1440) | E29: =IF(D29="","",IF(D29<0,"打日期",IF(D29*1440<=120,"J+2",IF(D29*1440<=240,"J+4",IF(D29*1440<=360,"J+6",IF(D29*1440<=480,"J+8","8以上"))))))
D30: =IF(OR(B30="",C30=""),"",ROUND((IF(C30<1,INT(B30)+C30,C30)-B30)*1440,0)/1440) | E30: =IF(D30="","",IF(D30<0,"打日期",IF(D30*1440<=120,"J+2",IF(D30*1440<=240,"J+4",IF(D30*1440<=360,"J+6",IF(D30*1440<=480,"J+8","8以上"))))))
D31: =IF(OR(B31="",C31=""),"",ROUND((IF(C31<1,INT(B31)+C31,C31)-B31)*1440,0)/1440) | E31: =IF(D31="","",IF(D31<0,"打日期",IF(D31*1440<=120,"J+2",IF(D31*1440<=240,"J+4",IF(D31*1440<=360,"J+6",IF(D31*1440<=480,"J+8","8以上"))))))
D32: =IF(OR(B32="",C32=""),"",ROUND((IF(C32<1,INT(B32)+C32,C32)-B32)*1440,0)/1440) | E32: =IF(D32="","",IF(D32<0,"打日期",IF(D32*1440<=120,"J+2",IF(D32*1440<=240,"J+4",IF(D32*1440<=360,"J+6",IF(D32*1440<=480,"J+8","8以上"))))))
D33: =IF(OR(B33="",C33=""),"",ROUND((IF(C33<1,INT(B33)+C33,C33)-B33)*1440,0)/1440) | E33: =IF(D33="","",IF(D33<0,"打日期",IF(D33*1440<=120,"J+2",IF(D33*1440<=240,"J+4",IF(D33*1440<=360,"J+6",IF(D33*1440<=480,"J+8","8以上"))))))
D34: =IF(OR(B34="",C34=""),"",ROUND((IF(C34<1,INT(B34)+C34,C34)-B34)*1440,0)/1440) | E34: =IF(D34="","",IF(D34<0,"打日期",IF(D34*1440<=120,"J+2",IF(D34*1440<=240,"J+4",IF(D34*1440<=360,"J+6",IF(D34*1440<=480,"J+8","8以上"))))))
... D37: =IF(OR(B37="",C37=""),"",ROUND((IF(C37<1,INT(B37)+C37,C37)-B37)*1440,0)/1440) | E37: =IF(D37="","",IF(D37<0,"打日期",IF(D37*1440<=120,"J+2",IF(D37*1440<=240,"J+4",IF(D37*1440<=360,"J+6",IF(D37*1440<=480,"J+8","8以上"))))))
A38: 十大都市:( 11時前交寄之郵件) 台北市(100-110)、基隆市(200~206)、桃園市(330)、中壢市(含平鎮，320、324)、台中市(400-408)、彰化市(500)、嘉義市(600)、台南市(700-709)、高雄市(800-804、806、807)互寄者。
A40: 製表: | C40: 主管:
A41: ="中和郵務股"&'02'!$G$2&'02'!$H$2&"份 區域內互寄 快捷郵遞時效表" -> 中和郵務股115年2月份 區域內互寄 快捷郵遞時效表
A42: 郵件號碼 | B42: 交寄時間 | C42: 交投時間 | D42: 時數 | E42: 時效
D43: =IF(OR(B43="",C43=""),"",ROUND((IF(C43<1,INT(B43)+C43,C43)-B43)*1440,0)/1440) | E43: =IF(D43="","",IF(D43<0,"打日期",IF(D43*1440<=120,"J+2",IF(D43*1440<=240,"J+4",IF(D43*1440<=360,"J+6",IF(D43*1440<=480,"J+8","8以上"))))))
D44: =IF(OR(B44="",C44=""),"",ROUND((IF(C44<1,INT(B44)+C44,C44)-B44)*1440,0)/1440) | E44: =IF(D44="","",IF(D44<0,"打日期",IF(D44*1440<=120,"J+2",IF(D44*1440<=240,"J+4",IF(D44*1440<=360,"J+6",IF(D44*1440<=480,"J+8","8以上"))))))
D45: =IF(OR(B45="",C45=""),"",ROUND((IF(C45<1,INT(B45)+C45,C45)-B45)*1440,0)/1440) | E45: =IF(D45="","",IF(D45<0,"打日期",IF(D45*1440<=120,"J+2",IF(D45*1440<=240,"J+4",IF(D45*1440<=360,"J+6",IF(D45*1440<=480,"J+8","8以上"))))))
D46: =IF(OR(B46="",C46=""),"",ROUND((IF(C46<1,INT(B46)+C46,C46)-B46)*1440,0)/1440) | E46: =IF(D46="","",IF(D46<0,"打日期",IF(D46*1440<=120,"J+2",IF(D46*1440<=240,"J+4",IF(D46*1440<=360,"J+6",IF(D46*1440<=480,"J+8","8以上"))))))
...

Sheet 03
A1: 中和郵局 抽測國內快捷情形報告單
G2: ='01'!G2 -> 115年 | H2: 3月
A3: 互寄地區 | C3: 抽測件數 | D3: J+2時 件數 | E3: J+2時 投遞率 | F3: J+4時 件數 | G3: J+4時 投遞率 | H3: J+6時 件數 | I3: J+6時 投遞率 | J3: J+8時 件數 | K3: J+8時 投遞率 | L3: 8時以上 件數 | M3: 8時以上 投遞率 | N3: 符合時效比例 | O3: 平均 (時)數
A4: 本收本投 | C4: =D4+F4+H4+J4+L4 -> 0 | D4: =COUNTIF(03子本!$E$3:$E$17,"J+2") -> 0 | E4: =IF($C4=0,"",D4/$C4) | F4: =COUNTIF(03子本!$E$3:$E$17,"J+4") -> 0 | G4: =IF($C4=0,"",F4/$C4) | H4: =COUNTIF(03子本!$E$3:$E$17,"J+6") -> 0 | I4: =IF($C4=0,"",H4/$C4) | J4: =COUNTIF(03子本!$E$3:$E$17,"J+8") -> 0 | K4: =IF($C4=0,"",J4/$C4) | L4: =COUNTIF(03子本!$E$3:$E$17,"8以上") -> 0 | M4: =IF($C4=0,"",L4/$C4) | N4: 1 | O4: =IF($C4=0,"",(D4*2+F4*4+H4*6+J4*8+L4*8)/$C4)
A5: 主要都市間互寄 | C5: =D5+F5+H5+J5+L5 -> 0 | D5: =COUNTIF(03子本!$E$23:$E$37,"J+2") -> 0 | E5: =IF($C5=0,"",D5/$C5) | F5: =COUNTIF(03子本!$E$23:$E$37,"J+4") -> 0 | G5: =IF($C5=0,"",F5/$C5) | H5: =COUNTIF(03子本!$E$23:$E$37,"J+6") -> 0 | I5: =IF($C5=0,"",H5/$C5) | J5: =COUNTIF(03子本!$E$23:$E$37,"J+8") -> 0 | K5: =IF($C5=0,"",J5/$C5) | L5: =COUNTIF(03子本!$E$23:$E$37,"8以上") -> 0 | M5: =IF($C5=0,"",L5/$C5) | N5: 1 | O5: =IF($C5=0,"",(D5*2+F5*4+H5*6+J5*8+L5*8)/$C5)
A6: 區域內互寄 (北北基、台中、高雄、中彰投地區) | C6: =D6+F6+H6+J6+L6 -> 0 | D6: =COUNTIF(03子本!$E$43:$E$57,"J+2") -> 0 | E6: =IF($C6=0,"",D6/$C6) | F6: =COUNTIF(03子本!$E$43:$E$57,"J+4") -> 0 | G6: =IF($C6=0,"",F6/$C6) | H6: =COUNTIF(03子本!$E$43:$E$57,"J+6") -> 0 | I6: =IF($C6=0,"",H6/$C6) | J6: =COUNTIF(03子本!$E$43:$E$57,"J+8") -> 0 | K6: =IF($C6=0,"",J6/$C6) | L6: =COUNTIF(03子本!$E$43:$E$57,"8以上") -> 0 | M6: =IF($C6=0,"",L6/$C6) | N6: 1 | O6: =IF($C6=0,"",(D6*2+F6*4+H6*6+J6*8+L6*8)/$C6)
A7: 其他轉口 | C7: =D7+F7+H7+J7+L7 -> 0 | D7: =COUNTIF(03子本!$E$63:$E$77,"J+2") -> 0 | E7: =IF($C7=0,"",D7/$C7) | F7: =COUNTIF(03子本!$E$63:$E$77,"J+4") -> 0 | G7: =IF($C7=0,"",F7/$C7) | H7: =COUNTIF(03子本!$E$63:$E$77,"J+6") -> 0 | I7: =IF($C7=0,"",H7/$C7) | J7: =COUNTIF(03子本!$E$63:$E$77,"J+8") -> 0 | K7: =IF($C7=0,"",J7/$C7) | L7: =COUNTIF(03子本!$E$63:$E$77,"8以上") -> 0 | M7: =IF($C7=0,"",L7/$C7) | N7: 1 | O7: =IF($C7=0,"",(D7*2+F7*4+H7*6+J7*8+L7*8)/$C7)
A8: 說明：
A9: 1 | B9: 為瞭解國內快捷郵件寄遞時效，各局快捷單位應透過MQ或本公司全球資訊網查詢系統抽測「本收本投」、「主要都市互寄」、「區域內互寄」、「其他轉口」4類，每月至少各10件（抽查紀錄列印或記錄郵件號碼留局備查，保存1年），抽測結果於次月5日前寄管轄郵局郵務科彙整，於8日前上傳主機。
A10: 2 | B10: 抽測樣本：本收本投以15時前交寄、主要都市互寄11時前交寄、區域間互寄13時前交寄之郵件抽測為主。
A11: 3 | B11: 寄遞時效：自「交寄郵件」到「郵件投遞中」之處理狀態時間計算，四小時以內者填「ｊ＋4時」欄；逾四小時不逾六小時者填「ｊ＋6時」欄，餘類推。抽測結果有不符合時效標準者，請將相關地名列出，並檢討改善。
A12: 4 | B12: 十大都市互寄係指台北市(100-110)、板橋市(220)、桃園市(330)、中壢市(含平鎮，320、324)、新竹市(300)、台中市(400-408)、彰化市(500)、嘉義市(600)、台南市(700-709)、高雄市(800-804、806、807)互寄者。該欄位僅由該十大都市互寄局就相關之郵件抽測情形填註。
A13: 5 | B13: 平均(時)數：((J+2小時投遞率)*2+(J+4小時投遞率)*4+(J+6小時投遞率)*6+(J+8小時投遞率)*8+(J+8小時以上投遞率)*8)/100。
B14: 製表: | F14: 主管:

Sheet 03子本
A1: ="中和郵務股"&'03'!$G$2&'03'!$H$2&"份 本口 快捷郵遞時效表" -> 中和郵務股115年3月份 本口 快捷郵遞時效表
A2: 郵件號碼 | B2: 交寄時間 | C2: 交投時間 | D2: 時數 | E2: 時效
D3: =IF(OR(B3="",C3=""),"",ROUND((IF(C3<1,INT(B3)+C3,C3)-B3)*1440,0)/1440) | E3: =IF(D3="","",IF(D3<0,"打日期",IF(D3*1440<=120,"J+2",IF(D3*1440<=240,"J+4",IF(D3*1440<=360,"J+6",IF(D3*1440<=480,"J+8","8以上"))))))
D4: =IF(OR(B4="",C4=""),"",ROUND((IF(C4<1,INT(B4)+C4,C4)-B4)*1440,0)/1440) | E4: =IF(D4="","",IF(D4<0,"打日期",IF(D4*1440<=120,"J+2",IF(D4*1440<=240,"J+4",IF(D4*1440<=360,"J+6",IF(D4*1440<=480,"J+8","8以上"))))))
D5: =IF(OR(B5="",C5=""),"",ROUND((IF(C5<1,INT(B5)+C5,C5)-B5)*1440,0)/1440) | E5: =IF(D5="","",IF(D5<0,"打日期",IF(D5*1440<=120,"J+2",IF(D5*1440<=240,"J+4",IF(D5*1440<=360,"J+6",IF(D5*1440<=480,"J+8","8以上"))))))
D6: =IF(OR(B6="",C6=""),"",ROUND((IF(C6<1,INT(B6)+C6,C6)-B6)*1440,0)/1440) | E6: =IF(D6="","",IF(D6<0,"打日期",IF(D6*1440<=120,"J+2",IF(D6*1440<=240,"J+4",IF(D6*1440<=360,"J+6",IF(D6*1440<=480,"J+8","8以上"))))))
D7: =IF(OR(B7="",C7=""),"",ROUND((IF(C7<1,INT(B7)+C7,C7)-B7)*1440,0)/1440) | E7: =IF(D7="","",IF(D7<0,"打日期",IF(D7*1440<=120,"J+2",IF(D7*1440<=240,"J+4",IF(D7*1440<=360,"J+6",IF(D7*1440<=480,"J+8","8以上"))))))
D8: =IF(OR(B8="",C8=""),"",ROUND((IF(C8<1,INT(B8)+C8,C8)-B8)*1440,0)/1440) | E8: =IF(D8="","",IF(D8<0,"打日期",IF(D8*1440<=120,"J+2",IF(D8*1440<=240,"J+4",IF(D8*1440<=360,"J+6",IF(D8*1440<=480,"J+8","8以上"))))))
D9: =IF(OR(B9="",C9=""),"",ROUND((IF(C9<1,INT(B9)+C9,C9)-B9)*1440,0)/1440) | E9: =IF(D9="","",IF(D9<0,"打日期",IF(D9*1440<=120,"J+2",IF(D9*1440<=240,"J+4",IF(D9*1440<=360,"J+6",IF(D9*1440<=480,"J+8","8以上"))))))
D10: =IF(OR(B10="",C10=""),"",ROUND((IF(C10<1,INT(B10)+C10,C10)-B10)*1440,0)/1440) | E10: =IF(D10="","",IF(D10<0,"打日期",IF(D10*1440<=120,"J+2",IF(D10*1440<=240,"J+4",IF(D10*1440<=360,"J+6",IF(D10*1440<=480,"J+8","8以上"))))))
D11: =IF(OR(B11="",C11=""),"",ROUND((IF(C11<1,INT(B11)+C11,C11)-B11)*1440,0)/1440) | E11: =IF(D11="","",IF(D11<0,"打日期",IF(D11*1440<=120,"J+2",IF(D11*1440<=240,"J+4",IF(D11*1440<=360,"J+6",IF(D11*1440<=480,"J+8","8以上"))))))
D12: =IF(OR(B12="",C12=""),"",ROUND((IF(C12<1,INT(B12)+C12,C12)-B12)*1440,0)/1440) | E12: =IF(D12="","",IF(D12<0,"打日期",IF(D12*1440<=120,"J+2",IF(D12*1440<=240,"J+4",IF(D12*1440<=360,"J+6",IF(D12*1440<=480,"J+8","8以上"))))))
D13: =IF(OR(B13="",C13=""),"",ROUND((IF(C13<1,INT(B13)+C13,C13)-B13)*1440,0)/1440) | E13: =IF(D13="","",IF(D13<0,"打日期",IF(D13*1440<=120,"J+2",IF(D13*1440<=240,"J+4",IF(D13*1440<=360,"J+6",IF(D13*1440<=480,"J+8","8以上"))))))
D14: =IF(OR(B14="",C14=""),"",ROUND((IF(C14<1,INT(B14)+C14,C14)-B14)*1440,0)/1440) | E14: =IF(D14="","",IF(D14<0,"打日期",IF(D14*1440<=120,"J+2",IF(D14*1440<=240,"J+4",IF(D14*1440<=360,"J+6",IF(D14*1440<=480,"J+8","8以上"))))))
... D17: =IF(OR(B17="",C17=""),"",ROUND((IF(C17<1,INT(B17)+C17,C17)-B17)*1440,0)/1440) | E17: =IF(D17="","",IF(D17<0,"打日期",IF(D17*1440<=120,"J+2",IF(D17*1440<=240,"J+4",IF(D17*1440<=360,"J+6",IF(D17*1440<=480,"J+8","8以上"))))))
A18: 本地互寄:( 15時前交寄之郵件) 板橋市22071~81、92
A20: 製表: | C20: 主管:
A21: ="中和郵務股"&'03'!$G$2&'03'!$H$2&"份 十大都會區 快捷郵遞時效表" -> 中和郵務股115年3月份 十大都會區 快捷郵遞時效表
A22: 郵件號碼 | B22: 交寄時間 | C22: 交投時間 | D22: 時數 | E22: 時效
D23: =IF(OR(B23="",C23=""),"",ROUND((IF(C23<1,INT(B23)+C23,C23)-B23)*1440,0)/1440) | E23: =IF(D23="","",IF(D23<0,"打日期",IF(D23*1440<=120,"J+2",IF(D23*1440<=240,"J+4",IF(D23*1440<=360,"J+6",IF(D23*1440<=480,"J+8","8以上"))))))
D24: =IF(OR(B24="",C24=""),"",ROUND((IF(C24<1,INT(B24)+C24,C24)-B24)*1440,0)/1440) | E24: =IF(D24="","",IF(D24<0,"打日期",IF(D24*1440<=120,"J+2",IF(D24*1440<=240,"J+4",IF(D24*1440<=360,"J+6",IF(D24*1440<=480,"J+8","8以上"))))))
D25: =IF(OR(B25="",C25=""),"",ROUND((IF(C25<1,INT(B25)+C25,C25)-B25)*1440,0)/1440) | E25: =IF(D25="","",IF(D25<0,"打日期",IF(D25*1440<=120,"J+2",IF(D25*1440<=240,"J+4",IF(D25*1440<=360,"J+6",IF(D25*1440<=480,"J+8","8以上"))))))
D26: =IF(OR(B26="",C26=""),"",ROUND((IF(C26<1,INT(B26)+C26,C26)-B26)*1440,0)/1440) | E26: =IF(D26="","",IF(D26<0,"打日期",IF(D26*1440<=120,"J+2",IF(D26*1440<=240,"J+4",IF(D26*1440<=360,"J+6",IF(D26*1440<=480,"J+8","8以上"))))))
D27: =IF(OR(B27="",C27=""),"",ROUND((IF(C27<1,INT(B27)+C27,C27)-B27)*1440,0)/1440) | E27: =IF(D27="","",IF(D27<0,"打日期",IF(D27*1440<=120,"J+2",IF(D27*1440<=240,"J+4",IF(D27*1440<=360,"J+6",IF(D27*1440<=480,"J+8","8以上"))))))
D28: =IF(OR(B28="",C28=""),"",ROUND((IF(C28<1,INT(B28)+C28,C28)-B28)*1440,0)/1440) | E28: =IF(D28="","",IF(D28<0,"打日期",IF(D28*1440<=120,"J+2",IF(D28*1440<=240,"J+4",IF(D28*1440<=360,"J+6",IF(D28*1440<=480,"J+8","8以上"))))))
D29: =IF(OR(B29="",C29=""),"",ROUND((IF(C29<1,INT(B29)+C29,C29)-B29)*1440,0)/1440) | E29: =IF(D29="","",IF(D29<0,"打日期",IF(D29*1440<=120,"J+2",IF(D29*1440<=240,"J+4",IF(D29*1440<=360,"J+6",IF(D29*1440<=480,"J+8","8以上"))))))
D30: =IF(OR(B30="",C30=""),"",ROUND((IF(C30<1,INT(B30)+C30,C30)-B30)*1440,0)/1440) | E30: =IF(D30="","",IF(D30<0,"打日期",IF(D30*1440<=120,"J+2",IF(D30*1440<=240,"J+4",IF(D30*1440<=360,"J+6",IF(D30*1440<=480,"J+8","8以上"))))))
D31: =IF(OR(B31="",C31=""),"",ROUND((IF(C31<1,INT(B31)+C31,C31)-B31)*1440,0)/1440) | E31: =IF(D31="","",IF(D31<0,"打日期",IF(D31*1440<=120,"J+2",IF(D31*1440<=240,"J+4",IF(D31*1440<=360,"J+6",IF(D31*1440<=480,"J+8","8以上"))))))
D32: =IF(OR(B32="",C32=""),"",ROUND((IF(C32<1,INT(B32)+C32,C32)-B32)*1440,0)/1440) | E32: =IF(D32="","",IF(D32<0,"打日期",IF(D32*1440<=120,"J+2",IF(D32*1440<=240,"J+4",IF(D32*1440<=360,"J+6",IF(D32*1440<=480,"J+8","8以上"))))))
D33: =IF(OR(B33="",C33=""),"",ROUND((IF(C33<1,INT(B33)+C33,C33)-B33)*1440,0)/1440) | E33: =IF(D33="","",IF(D33<0,"打日期",IF(D33*1440<=120,"J+2",IF(D33*1440<=240,"J+4",IF(D33*1440<=360,"J+6",IF(D33*1440<=480,"J+8","8以上"))))))
D34: =IF(OR(B34="",C34=""),"",ROUND((IF(C34<1,INT(B34)+C34,C34)-B34)*1440,0)/1440) | E34: =IF(D34="","",IF(D34<0,"打日期",IF(D34*1440<=120,"J+2",IF(D34*1440<=240,"J+4",IF(D34*1440<=360,"J+6",IF(D34*1440<=480,"J+8","8以上"))))))
... D37: =IF(OR(B37="",C37=""),"",ROUND((IF(C37<1,INT(B37)+C37,C37)-B37)*1440,0)/1440) | E37: =IF(D37="","",IF(D37<0,"打日期",IF(D37*1440<=120,"J+2",IF(D37*1440<=240,"J+4",IF(D37*1440<=360,"J+6",IF(D37*1440<=480,"J+8","8以上"))))))
A38: 十大都市:( 11時前交寄之郵件) 台北市(100-110)、基隆市(200~206)、桃園市(330)、中壢市(含平鎮，320、324)、台中市(400-408)、彰化市(500)、嘉義市(600)、台南市(700-709)、高雄市(800-804、806、807)互寄者。
A40: 製表: | C40: 主管:
A41: ="中和郵務股"&'03'!$G$2&'03'!$H$2&"份 區域內互寄 快捷郵遞時效表" -> 中和郵務股115年3月份 區域內互寄 快捷郵遞時效表
A42: 郵件號碼 | B42: 交寄時間 | C42: 交投時間 | D42: 時數 | E42: 時效
D43: =IF(OR(B43="",C43=""),"",ROUND((IF(C43<1,INT(B43)+C43,C43)-B43)*1440,0)/1440) | E43: =IF(D43="","",IF(D43<0,"打日期",IF(D43*1440<=120,"J+2",IF(D43*1440<=240,"J+4",IF(D43*1440<=360,"J+6",IF(D43*1440<=480,"J+8","8以上"))))))
D44: =IF(OR(B44="",C44=""),"",ROUND((IF(C44<1,INT(B44)+C44,C44)-B44)*1440,0)/1440) | E44: =IF(D44="","",IF(D44<0,"打日期",IF(D44*1440<=120,"J+2",IF(D44*1440<=240,"J+4",IF(D44*1440<=360,"J+6",IF(D44*1440<=480,"J+8","8以上"))))))
D45: =IF(OR(B45="",C45=""),"",ROUND((IF(C45<1,INT(B45)+C45,C45)-B45)*1440,0)/1440) | E45: =IF(D45="","",IF(D45<0,"打日期",IF(D45*1440<=120,"J+2",IF(D45*1440<=240,"J+4",IF(D45*1440<=360,"J+6",IF(D45*1440<=480,"J+8","8以上"))))))
D46: =IF(OR(B46="",C46=""),"",ROUND((IF(C46<1,INT(B46)+C46,C46)-B46)*1440,0)/1440) | E46: =IF(D46="","",IF(D46<0,"打日期",IF(D46*1440<=120,"J+2",IF(D46*1440<=240,"J+4",IF(D46*1440<=360,"J+6",IF(D46*1440<=480,"J+8","8以上"))))))
...

Sheet 04
A1: 中和郵局 抽測國內快捷情形報告單
G2: ='01'!G2 -> 115年 | H2: 4月
A3: 互寄地區 | C3: 抽測件數 | D3: J+2時 件數 | E3: J+2時 投遞率 | F3: J+4時 件數 | G3: J+4時 投遞率 | H3: J+6時 件數 | I3: J+6時 投遞率 | J3: J+8時 件數 | K3: J+8時 投遞率 | L3: 8時以上 件數 | M3: 8時以上 投遞率 | N3: 符合時效比例 | O3: 平均 (時)數
A4: 本收本投 | C4: =D4+F4+H4+J4+L4 -> 0 | D4: =COUNTIF(04子本!$E$3:$E$17,"J+2") -> 0 | E4: =IF($C4=0,"",D4/$C4) | F4: =COUNTIF(04子本!$E$3:$E$17,"J+4") -> 0 | G4: =IF($C4=0,"",F4/$C4) | H4: =COUNTIF(04子本!$E$3:$E$17,"J+6") -> 0 | I4: =IF($C4=0,"",H4/$C4) | J4: =COUNTIF(04子本!$E$3:$E$17,"J+8") -> 0 | K4: =IF($C4=0,"",J4/$C4) | L4: =COUNTIF(04子本!$E$3:$E$17,"8以上") -> 0 | M4: =IF($C4=0,"",L4/$C4) | N4: 1 | O4: =IF($C4=0,"",(D4*2+F4*4+H4*6+J4*8+L4*8)/$C4)
A5: 主要都市間互寄 | C5: =D5+F5+H5+J5+L5 -> 0 | D5: =COUNTIF(04子本!$E$23:$E$37,"J+2") -> 0 | E5: =IF($C5=0,"",D5/$C5) | F5: =COUNTIF(04子本!$E$23:$E$37,"J+4") -> 0 | G5: =IF($C5=0,"",F5/$C5) | H5: =COUNTIF(04子本!$E$23:$E$37,"J+6") -> 0 | I5: =IF($C5=0,"",H5/$C5) | J5: =COUNTIF(04子本!$E$23:$E$37,"J+8") -> 0 | K5: =IF($C5=0,"",J5/$C5) | L5: =COUNTIF(04子本!$E$23:$E$37,"8以上") -> 0 | M5: =IF($C5=0,"",L5/$C5) | N5: 1 | O5: =IF($C5=0,"",(D5*2+F5*4+H5*6+J5*8+L5*8)/$C5)
A6: 區域內互寄 (北北基、台中、高雄、中彰投地區) | C6: =D6+F6+H6+J6+L6 -> 0 | D6: =COUNTIF(04子本!$E$43:$E$57,"J+2") -> 0 | E6: =IF($C6=0,"",D6/$C6) | F6: =COUNTIF(04子本!$E$43:$E$57,"J+4") -> 0 | G6: =IF($C6=0,"",F6/$C6) | H6: =COUNTIF(04子本!$E$43:$E$57,"J+6") -> 0 | I6: =IF($C6=0,"",H6/$C6) | J6: =COUNTIF(04子本!$E$43:$E$57,"J+8") -> 0 | K6: =IF($C6=0,"",J6/$C6) | L6: =COUNTIF(04子本!$E$43:$E$57,"8以上") -> 0 | M6: =IF($C6=0,"",L6/$C6) | N6: 1 | O6: =IF($C6=0,"",(D6*2+F6*4+H6*6+J6*8+L6*8)/$C6)
A7: 其他轉口 | C7: =D7+F7+H7+J7+L7 -> 0 | D7: =COUNTIF(04子本!$E$63:$E$77,"J+2") -> 0 | E7: =IF($C7=0,"",D7/$C7) | F7: =COUNTIF(04子本!$E$63:$E$77,"J+4") -> 0 | G7: =IF($C7=0,"",F7/$C7) | H7: =COUNTIF(04子本!$E$63:$E$77,"J+6") -> 0 | I7: =IF($C7=0,"",H7/$C7) | J7: =COUNTIF(04子本!$E$63:$E$77,"J+8") -> 0 | K7: =IF($C7=0,"",J7/$C7) | L7: =COUNTIF(04子本!$E$63:$E$77,"8以上") -> 0 | M7: =IF($C7=0,"",L7/$C7) | N7: 1 | O7: =IF($C7=0,"",(D7*2+F7*4+H7*6+J7*8+L7*8)/$C7)
A8: 說明：
A9: 1 | B9: 為瞭解國內快捷郵件寄遞時效，各局快捷單位應透過MQ或本公司全球資訊網查詢系統抽測「本收本投」、「主要都市互寄」、「區域內互寄」、「其他轉口」4類，每月至少各10件（抽查紀錄列印或記錄郵件號碼留局備查，保存1年），抽測結果於次月5日前寄管轄郵局郵務科彙整，於8日前上傳主機。
A10: 2 | B10: 抽測樣本：本收本投以15時前交寄、主要都市互寄11時前交寄、區域間互寄13時前交寄之郵件抽測為主。
A11: 3 | B11: 寄遞時效：自「交寄郵件」到「郵件投遞中」之處理狀態時間計算，四小時以內者填「ｊ＋4時」欄；逾四小時不逾六小時者填「ｊ＋6時」欄，餘類推。抽測結果有不符合時效標準者，請將相關地名列出，並檢討改善。
A12: 4 | B12: 十大都市互寄係指台北市(100-110)、板橋市(220)、桃園市(330)、中壢市(含平鎮，320、324)、新竹市(300)、台中市(400-408)、彰化市(500)、嘉義市(600)、台南市(700-709)、高雄市(800-804、806、807)互寄者。該欄位僅由該十大都市互寄局就相關之郵件抽測情形填註。
A13: 5 | B13: 平均(時)數：((J+2小時投遞率)*2+(J+4小時投遞率)*4+(J+6小時投遞率)*6+(J+8小時投遞率)*8+(J+8小時以上投遞率)*8)/100。
B14: 製表: | F14: 主管:

Sheet 04子本
A1: ="中和郵務股"&'04'!$G$2&'04'!$H$2&"份 本口 快捷郵遞時效表" -> 中和郵務股115年4月份 本口 快捷郵遞時效表
A2: 郵件號碼 | B2: 交寄時間 | C2: 交投時間 | D2: 時數 | E2: 時效
D3: =IF(OR(B3="",C3=""),"",ROUND((IF(C3<1,INT(B3)+C3,C3)-B3)*1440,0)/1440) | E3: =IF(D3="","",IF(D3<0,"打日期",IF(D3*1440<=120,"J+2",IF(D3*1440<=240,"J+4",IF(D3*1440<=360,"J+6",IF(D3*1440<=480,"J+8","8以上"))))))
D4: =IF(OR(B4="",C4=""),"",ROUND((IF(C4<1,INT(B4)+C4,C4)-B4)*1440,0)/1440) | E4: =IF(D4="","",IF(D4<0,"打日期",IF(D4*1440<=120,"J+2",IF(D4*1440<=240,"J+4",IF(D4*1440<=360,"J+6",IF(D4*1440<=480,"J+8","8以上"))))))
D5: =IF(OR(B5="",C5=""),"",ROUND((IF(C5<1,INT(B5)+C5,C5)-B5)*1440,0)/1440) | E5: =IF(D5="","",IF(D5<0,"打日期",IF(D5*1440<=120,"J+2",IF(D5*1440<=240,"J+4",IF(D5*1440<=360,"J+6",IF(D5*1440<=480,"J+8","8以上"))))))
D6: =IF(OR(B6="",C6=""),"",ROUND((IF(C6<1,INT(B6)+C6,C6)-B6)*1440,0)/1440) | E6: =IF(D6="","",IF(D6<0,"打日期",IF(D6*1440<=120,"J+2",IF(D6*1440<=240,"J+4",IF(D6*1440<=360,"J+6",IF(D6*1440<=480,"J+8","8以上"))))))
D7: =IF(OR(B7="",C7=""),"",ROUND((IF(C7<1,INT(B7)+C7,C7)-B7)*1440,0)/1440) | E7: =IF(D7="","",IF(D7<0,"打日期",IF(D7*1440<=120,"J+2",IF(D7*1440<=240,"J+4",IF(D7*1440<=360,"J+6",IF(D7*1440<=480,"J+8","8以上"))))))
D8: =IF(OR(B8="",C8=""),"",ROUND((IF(C8<1,INT(B8)+C8,C8)-B8)*1440,0)/1440) | E8: =IF(D8="","",IF(D8<0,"打日期",IF(D8*1440<=120,"J+2",IF(D8*1440<=240,"J+4",IF(D8*1440<=360,"J+6",IF(D8*1440<=480,"J+8","8以上"))))))
D9: =IF(OR(B9="",C9=""),"",ROUND((IF(C9<1,INT(B9)+C9,C9)-B9)*1440,0)/1440) | E9: =IF(D9="","",IF(D9<0,"打日期",IF(D9*1440<=120,"J+2",IF(D9*1440<=240,"J+4",IF(D9*1440<=360,"J+6",IF(D9*1440<=480,"J+8","8以上"))))))
D10: =IF(OR(B10="",C10=""),"",ROUND((IF(C10<1,INT(B10)+C10,C10)-B10)*1440,0)/1440) | E10: =IF(D10="","",IF(D10<0,"打日期",IF(D10*1440<=120,"J+2",IF(D10*1440<=240,"J+4",IF(D10*1440<=360,"J+6",IF(D10*1440<=480,"J+8","8以上"))))))
D11: =IF(OR(B11="",C11=""),"",ROUND((IF(C11<1,INT(B11)+C11,C11)-B11)*1440,0)/1440) | E11: =IF(D11="","",IF(D11<0,"打日期",IF(D11*1440<=120,"J+2",IF(D11*1440<=240,"J+4",IF(D11*1440<=360,"J+6",IF(D11*1440<=480,"J+8","8以上"))))))
D12: =IF(OR(B12="",C12=""),"",ROUND((IF(C12<1,INT(B12)+C12,C12)-B12)*1440,0)/1440) | E12: =IF(D12="","",IF(D12<0,"打日期",IF(D12*1440<=120,"J+2",IF(D12*1440<=240,"J+4",IF(D12*1440<=360,"J+6",IF(D12*1440<=480,"J+8","8以上"))))))
D13: =IF(OR(B13="",C13=""),"",ROUND((IF(C13<1,INT(B13)+C13,C13)-B13)*1440,0)/1440) | E13: =IF(D13="","",IF(D13<0,"打日期",IF(D13*1440<=120,"J+2",IF(D13*1440<=240,"J+4",IF(D13*1440<=360,"J+6",IF(D13*1440<=480,"J+8","8以上"))))))
D14: =IF(OR(B14="",C14=""),"",ROUND((IF(C14<1,INT(B14)+C14,C14)-B14)*1440,0)/1440) | E14: =IF(D14="","",IF(D14<0,"打日期",IF(D14*1440<=120,"J+2",IF(D14*1440<=240,"J+4",IF(D14*1440<=360,"J+6",IF(D14*1440<=480,"J+8","8以上"))))))
... D17: =IF(OR(B17="",C17=""),"",ROUND((IF(C17<1,INT(B17)+C17,C17)-B17)*1440,0)/1440) | E17: =IF(D17="","",IF(D17<0,"打日期",IF(D17*1440<=120,"J+2",IF(D17*1440<=240,"J+4",IF(D17*1440<=360,"J+6",IF(D17*1440<=480,"J+8","8以上"))))))
A18: 本地互寄:( 15時前交寄之郵件) 板橋市22071~81、92
A20: 製表: | C20: 主管:
A21: ="中和郵務股"&'04'!$G$2&'04'!$H$2&"份 十大都會區 快捷郵遞時效表" -> 中和郵務股115年4月份 十大都會區 快捷郵遞時效表
A22: 郵件號碼 | B22: 交寄時間 | C22: 交投時間 | D22: 時數 | E22: 時效
D23: =IF(OR(B23="",C23=""),"",ROUND((IF(C23<1,INT(B23)+C23,C23)-B23)*1440,0)/1440) | E23: =IF(D23="","",IF(D23<0,"打日期",IF(D23*1440<=120,"J+2",IF(D23*1440<=240,"J+4",IF(D23*1440<=360,"J+6",IF(D23*1440<=480,"J+8","8以上"))))))
D24: =IF(OR(B24="",C24=""),"",ROUND((IF(C24<1,INT(B24)+C24,C24)-B24)*1440,0)/1440) | E24: =IF(D24="","",IF(D24<0,"打日期",IF(D24*1440<=120,"J+2",IF(D24*1440<=240,"J+4",IF(D24*1440<=360,"J+6",IF(D24*1440<=480,"J+8","8以上"))))))
D25: =IF(OR(B25="",C25=""),"",ROUND((IF(C25<1,INT(B25)+C25,C25)-B25)*1440,0)/1440) | E25: =IF(D25="","",IF(D25<0,"打日期",IF(D25*1440<=120,"J+2",IF(D25*1440<=240,"J+4",IF(D25*1440<=360,"J+6",IF(D25*1440<=480,"J+8","8以上"))))))
D26: =IF(OR(B26="",C26=""),"",ROUND((IF(C26<1,INT(B26)+C26,C26)-B26)*1440,0)/1440) | E26: =IF(D26="","",IF(D26<0,"打日期",IF(D26*1440<=120,"J+2",IF(D26*1440<=240,"J+4",IF(D26*1440<=360,"J+6",IF(D26*1440<=480,"J+8","8以上"))))))
D27: =IF(OR(B27="",C27=""),"",ROUND((IF(C27<1,INT(B27)+C27,C27)-B27)*1440,0)/1440) | E27: =IF(D27="","",IF(D27<0,"打日期",IF(D27*1440<=120,"J+2",IF(D27*1440<=240,"J+4",IF(D27*1440<=360,"J+6",IF(D27*1440<=480,"J+8","8以上"))))))
D28: =IF(OR(B28="",C28=""),"",ROUND((IF(C28<1,INT(B28)+C28,C28)-B28)*1440,0)/1440) | E28: =IF(D28="","",IF(D28<0,"打日期",IF(D28*1440<=120,"J+2",IF(D28*1440<=240,"J+4",IF(D28*1440<=360,"J+6",IF(D28*1440<=480,"J+8","8以上"))))))
D29: =IF(OR(B29="",C29=""),"",ROUND((IF(C29<1,INT(B29)+C29,C29)-B29)*1440,0)/1440) | E29: =IF(D29="","",IF(D29<0,"打日期",IF(D29*1440<=120,"J+2",IF(D29*1440<=240,"J+4",IF(D29*1440<=360,"J+6",IF(D29*1440<=480,"J+8","8以上"))))))
D30: =IF(OR(B30="",C30=""),"",ROUND((IF(C30<1,INT(B30)+C30,C30)-B30)*1440,0)/1440) | E30: =IF(D30="","",IF(D30<0,"打日期",IF(D30*1440<=120,"J+2",IF(D30*1440<=240,"J+4",IF(D30*1440<=360,"J+6",IF(D30*1440<=480,"J+8","8以上"))))))
D31: =IF(OR(B31="",C31=""),"",ROUND((IF(C31<1,INT(B31)+C31,C31)-B31)*1440,0)/1440) | E31: =IF(D31="","",IF(D31<0,"打日期",IF(D31*1440<=120,"J+2",IF(D31*1440<=240,"J+4",IF(D31*1440<=360,"J+6",IF(D31*1440<=480,"J+8","8以上"))))))
D32: =IF(OR(B32="",C32=""),"",ROUND((IF(C32<1,INT(B32)+C32,C32)-B32)*1440,0)/1440) | E32: =IF(D32="","",IF(D32<0,"打日期",IF(D32*1440<=120,"J+2",IF(D32*1440<=240,"J+4",IF(D32*1440<=360,"J+6",IF(D32*1440<=480,"J+8","8以上"))))))
D33: =IF(OR(B33="",C33=""),"",ROUND((IF(C33<1,INT(B33)+C33,C33)-B33)*1440,0)/1440) | E33: =IF(D33="","",IF(D33<0,"打日期",IF(D33*1440<=120,"J+2",IF(D33*1440<=240,"J+4",IF(D33*1440<=360,"J+6",IF(D33*1440<=480,"J+8","8以上"))))))
D34: =IF(OR(B34="",C34=""),"",ROUND((IF(C34<1,INT(B34)+C34,C34)-B34)*1440,0)/1440) | E34: =IF(D34="","",IF(D34<0,"打日期",IF(D34*1440<=120,"J+2",IF(D34*1440<=240,"J+4",IF(D34*1440<=360,"J+6",IF(D34*1440<=480,"J+8","8以上"))))))
... D37: =IF(OR(B37="",C37=""),"",ROUND((IF(C37<1,INT(B37)+C37,C37)-B37)*1440,0)/1440) | E37: =IF(D37="","",IF(D37<0,"打日期",IF(D37*1440<=120,"J+2",IF(D37*1440<=240,"J+4",IF(D37*1440<=360,"J+6",IF(D37*1440<=480,"J+8","8以上"))))))
A38: 十大都市:( 11時前交寄之郵件) 台北市(100-110)、基隆市(200~206)、桃園市(330)、中壢市(含平鎮，320、324)、台中市(400-408)、彰化市(500)、嘉義市(600)、台南市(700-709)、高雄市(800-804、806、807)互寄者。
A40: 製表: | C40: 主管:
A41: ="中和郵務股"&'04'!$G$2&'04'!$H$2&"份 區域內互寄 快捷郵遞時效表" -> 中和郵務股115年4月份 區域內互寄 快捷郵遞時效表
A42: 郵件號碼 | B42: 交寄時間 | C42: 交投時間 | D42: 時數 | E42: 時效
D43: =IF(OR(B43="",C43=""),"",ROUND((IF(C43<1,INT(B43)+C43,C43)-B43)*1440,0)/1440) | E43: =IF(D43="","",IF(D43<0,"打日期",IF(D43*1440<=120,"J+2",IF(D43*1440<=240,"J+4",IF(D43*1440<=360,"J+6",IF(D43*1440<=480,"J+8","8以上"))))))
D44: =IF(OR(B44="",C44=""),"",ROUND((IF(C44<1,INT(B44)+C44,C44)-B44)*1440,0)/1440) | E44: =IF(D44="","",IF(D44<0,"打日期",IF(D44*1440<=120,"J+2",IF(D44*1440<=240,"J+4",IF(D44*1440<=360,"J+6",IF(D44*1440<=480,"J+8","8以上"))))))
D45: =IF(OR(B45="",C45=""),"",ROUND((IF(C45<1,INT(B45)+C45,C45)-B45)*1440,0)/1440) | E45: =IF(D45="","",IF(D45<0,"打日期",IF(D45*1440<=120,"J+2",IF(D45*1440<=240,"J+4",IF(D45*1440<=360,"J+6",IF(D45*1440<=480,"J+8","8以上"))))))
D46: =IF(OR(B46="",C46=""),"",ROUND((IF(C46<1,INT(B46)+C46,C46)-B46)*1440,0)/1440) | E46: =IF(D46="","",IF(D46<0,"打日期",IF(D46*1440<=120,"J+2",IF(D46*1440<=240,"J+4",IF(D46*1440<=360,"J+6",IF(D46*1440<=480,"J+8","8以上"))))))
...

Sheet 05
A1: 中和郵局 抽測國內快捷情形報告單
G2: ='01'!G2 -> 115年 | H2: 5月
A3: 互寄地區 | C3: 抽測件數 | D3: J+2時 件數 | E3: J+2時 投遞率 | F3: J+4時 件數 | G3: J+4時 投遞率 | H3: J+6時 件數 | I3: J+6時 投遞率 | J3: J+8時 件數 | K3: J+8時 投遞率 | L3: 8時以上 件數 | M3: 8時以上 投遞率 | N3: 符合時效比例 | O3: 平均 (時)數
A4: 本收本投 | C4: =D4+F4+H4+J4+L4 -> 0 | D4: =COUNTIF(05子本!$E$3:$E$17,"J+2") -> 0 | E4: =IF($C4=0,"",D4/$C4) | F4: =COUNTIF(05子本!$E$3:$E$17,"J+4") -> 0 | G4: =IF($C4=0,"",F4/$C4) | H4: =COUNTIF(05子本!$E$3:$E$17,"J+6") -> 0 | I4: =IF($C4=0,"",H4/$C4) | J4: =COUNTIF(05子本!$E$3:$E$17,"J+8") -> 0 | K4: =IF($C4=0,"",J4/$C4) | L4: =COUNTIF(05子本!$E$3:$E$17,"8以上") -> 0 | M4: =IF($C4=0,"",L4/$C4) | N4: 1 | O4: =IF($C4=0,"",(D4*2+F4*4+H4*6+J4*8+L4*8)/$C4)
A5: 主要都市間互寄 | C5: =D5+F5+H5+J5+L5 -> 0 | D5: =COUNTIF(05子本!$E$23:$E$37,"J+2") -> 0 | E5: =IF($C5=0,"",D5/$C5) | F5: =COUNTIF(05子本!$E$23:$E$37,"J+4") -> 0 | G5: =IF($C5=0,"",F5/$C5) | H5: =COUNTIF(05子本!$E$23:$E$37,"J+6") -> 0 | I5: =IF($C5=0,"",H5/$C5) | J5: =COUNTIF(05子本!$E$23:$E$37,"J+8") -> 0 | K5: =IF($C5=0,"",J5/$C5) | L5: =COUNTIF(05子本!$E$23:$E$37,"8以上") -> 0 | M5: =IF($C5=0,"",L5/$C5) | N5: 1 | O5: =IF($C5=0,"",(D5*2+F5*4+H5*6+J5*8+L5*8)/$C5)
A6: 區域內互寄 (北北基、台中、高雄、中彰投地區) | C6: =D6+F6+H6+J6+L6 -> 0 | D6: =COUNTIF(05子本!$E$43:$E$57,"J+2") -> 0 | E6: =IF($C6=0,"",D6/$C6) | F6: =COUNTIF(05子本!$E$43:$E$57,"J+4") -> 0 | G6: =IF($C6=0,"",F6/$C6) | H6: =COUNTIF(05子本!$E$43:$E$57,"J+6") -> 0 | I6: =IF($C6=0,"",H6/$C6) | J6: =COUNTIF(05子本!$E$43:$E$57,"J+8") -> 0 | K6: =IF($C6=0,"",J6/$C6) | L6: =COUNTIF(05子本!$E$43:$E$57,"8以上") -> 0 | M6: =IF($C6=0,"",L6/$C6) | N6: 1 | O6: =IF($C6=0,"",(D6*2+F6*4+H6*6+J6*8+L6*8)/$C6)
A7: 其他轉口 | C7: =D7+F7+H7+J7+L7 -> 0 | D7: =COUNTIF(05子本!$E$63:$E$77,"J+2") -> 0 | E7: =IF($C7=0,"",D7/$C7) | F7: =COUNTIF(05子本!$E$63:$E$77,"J+4") -> 0 | G7: =IF($C7=0,"",F7/$C7) | H7: =COUNTIF(05子本!$E$63:$E$77,"J+6") -> 0 | I7: =IF($C7=0,"",H7/$C7) | J7: =COUNTIF(05子本!$E$63:$E$77,"J+8") -> 0 | K7: =IF($C7=0,"",J7/$C7) | L7: =COUNTIF(05子本!$E$63:$E$77,"8以上") -> 0 | M7: =IF($C7=0,"",L7/$C7) | N7: 1 | O7: =IF($C7=0,"",(D7*2+F7*4+H7*6+J7*8+L7*8)/$C7)
A8: 說明：
A9: 1 | B9: 為瞭解國內快捷郵件寄遞時效，各局快捷單位應透過MQ或本公司全球資訊網查詢系統抽測「本收本投」、「主要都市互寄」、「區域內互寄」、「其他轉口」4類，每月至少各10件（抽查紀錄列印或記錄郵件號碼留局備查，保存1年），抽測結果於次月5日前寄管轄郵局郵務科彙整，於8日前上傳主機。
A10: 2 | B10: 抽測樣本：本收本投以15時前交寄、主要都市互寄11時前交寄、區域間互寄13時前交寄之郵件抽測為主。
A11: 3 | B11: 寄遞時效：自「交寄郵件」到「郵件投遞中」之處理狀態時間計算，四小時以內者填「ｊ＋4時」欄；逾四小時不逾六小時者填「ｊ＋6時」欄，餘類推。抽測結果有不符合時效標準者，請將相關地名列出，並檢討改善。
A12: 4 | B12: 十大都市互寄係指台北市(100-110)、板橋市(220)、桃園市(330)、中壢市(含平鎮，320、324)、新竹市(300)、台中市(400-408)、彰化市(500)、嘉義市(600)、台南市(700-709)、高雄市(800-804、806、807)互寄者。該欄位僅由該十大都市互寄局就相關之郵件抽測情形填註。
A13: 5 | B13: 平均(時)數：((J+2小時投遞率)*2+(J+4小時投遞率)*4+(J+6小時投遞率)*6+(J+8小時投遞率)*8+(J+8小時以上投遞率)*8)/100。
B14: 製表: | F14: 主管:

Sheet 05子本
A1: ="中和郵務股"&'05'!$G$2&'05'!$H$2&"份 本口 快捷郵遞時效表" -> 中和郵務股115年5月份 本口 快捷郵遞時效表
A2: 郵件號碼 | B2: 交寄時間 | C2: 交投時間 | D2: 時數 | E2: 時效
D3: =IF(OR(B3="",C3=""),"",ROUND((IF(C3<1,INT(B3)+C3,C3)-B3)*1440,0)/1440) | E3: =IF(D3="","",IF(D3<0,"打日期",IF(D3*1440<=120,"J+2",IF(D3*1440<=240,"J+4",IF(D3*1440<=360,"J+6",IF(D3*1440<=480,"J+8","8以上"))))))
D4: =IF(OR(B4="",C4=""),"",ROUND((IF(C4<1,INT(B4)+C4,C4)-B4)*1440,0)/1440) | E4: =IF(D4="","",IF(D4<0,"打日期",IF(D4*1440<=120,"J+2",IF(D4*1440<=240,"J+4",IF(D4*1440<=360,"J+6",IF(D4*1440<=480,"J+8","8以上"))))))
D5: =IF(OR(B5="",C5=""),"",ROUND((IF(C5<1,INT(B5)+C5,C5)-B5)*1440,0)/1440) | E5: =IF(D5="","",IF(D5<0,"打日期",IF(D5*1440<=120,"J+2",IF(D5*1440<=240,"J+4",IF(D5*1440<=360,"J+6",IF(D5*1440<=480,"J+8","8以上"))))))
D6: =IF(OR(B6="",C6=""),"",ROUND((IF(C6<1,INT(B6)+C6,C6)-B6)*1440,0)/1440) | E6: =IF(D6="","",IF(D6<0,"打日期",IF(D6*1440<=120,"J+2",IF(D6*1440<=240,"J+4",IF(D6*1440<=360,"J+6",IF(D6*1440<=480,"J+8","8以上"))))))
D7: =IF(OR(B7="",C7=""),"",ROUND((IF(C7<1,INT(B7)+C7,C7)-B7)*1440,0)/1440) | E7: =IF(D7="","",IF(D7<0,"打日期",IF(D7*1440<=120,"J+2",IF(D7*1440<=240,"J+4",IF(D7*1440<=360,"J+6",IF(D7*1440<=480,"J+8","8以上"))))))
D8: =IF(OR(B8="",C8=""),"",ROUND((IF(C8<1,INT(B8)+C8,C8)-B8)*1440,0)/1440) | E8: =IF(D8="","",IF(D8<0,"打日期",IF(D8*1440<=120,"J+2",IF(D8*1440<=240,"J+4",IF(D8*1440<=360,"J+6",IF(D8*1440<=480,"J+8","8以上"))))))
D9: =IF(OR(B9="",C9=""),"",ROUND((IF(C9<1,INT(B9)+C9,C9)-B9)*1440,0)/1440) | E9: =IF(D9="","",IF(D9<0,"打日期",IF(D9*1440<=120,"J+2",IF(D9*1440<=240,"J+4",IF(D9*1440<=360,"J+6",IF(D9*1440<=480,"J+8","8以上"))))))
D10: =IF(OR(B10="",C10=""),"",ROUND((IF(C10<1,INT(B10)+C10,C10)-B10)*1440,0)/1440) | E10: =IF(D10="","",IF(D10<0,"打日期",IF(D10*1440<=120,"J+2",IF(D10*1440<=240,"J+4",IF(D10*1440<=360,"J+6",IF(D10*1440<=480,"J+8","8以上"))))))
D11: =IF(OR(B11="",C11=""),"",ROUND((IF(C11<1,INT(B11)+C11,C11)-B11)*1440,0)/1440) | E11: =IF(D11="","",IF(D11<0,"打日期",IF(D11*1440<=120,"J+2",IF(D11*1440<=240,"J+4",IF(D11*1440<=360,"J+6",IF(D11*1440<=480,"J+8","8以上"))))))
D12: =IF(OR(B12="",C12=""),"",ROUND((IF(C12<1,INT(B12)+C12,C12)-B12)*1440,0)/1440) | E12: =IF(D12="","",IF(D12<0,"打日期",IF(D12*1440<=120,"J+2",IF(D12*1440<=240,"J+4",IF(D12*1440<=360,"J+6",IF(D12*1440<=480,"J+8","8以上"))))))
D13: =IF(OR(B13="",C13=""),"",ROUND((IF(C13<1,INT(B13)+C13,C13)-B13)*1440,0)/1440) | E13: =IF(D13="","",IF(D13<0,"打日期",IF(D13*1440<=120,"J+2",IF(D13*1440<=240,"J+4",IF(D13*1440<=360,"J+6",IF(D13*1440<=480,"J+8","8以上"))))))
D14: =IF(OR(B14="",C14=""),"",ROUND((IF(C14<1,INT(B14)+C14,C14)-B14)*1440,0)/1440) | E14: =IF(D14="","",IF(D14<0,"打日期",IF(D14*1440<=120,"J+2",IF(D14*1440<=240,"J+4",IF(D14*1440<=360,"J+6",IF(D14*1440<=480,"J+8","8以上"))))))
... D17: =IF(OR(B17="",C17=""),"",ROUND((IF(C17<1,INT(B17)+C17,C17)-B17)*1440,0)/1440) | E17: =IF(D17="","",IF(D17<0,"打日期",IF(D17*1440<=120,"J+2",IF(D17*1440<=240,"J+4",IF(D17*1440<=360,"J+6",IF(D17*1440<=480,"J+8","8以上"))))))
A18: 本地互寄:( 15時前交寄之郵件) 板橋市22071~81、92
A20: 製表: | C20: 主管:
A21: ="中和郵務股"&'05'!$G$2&'05'!$H$2&"份 十大都會區 快捷郵遞時效表" -> 中和郵務股115年5月份 十大都會區 快捷郵遞時效表
A22: 郵件號碼 | B22: 交寄時間 | C22: 交投時間 | D22: 時數 | E22: 時效
D23: =IF(OR(B23="",C23=""),"",ROUND((IF(C23<1,INT(B23)+C23,C23)-B23)*1440,0)/1440) | E23: =IF(D23="","",IF(D23<0,"打日期",IF(D23*1440<=120,"J+2",IF(D23*1440<=240,"J+4",IF(D23*1440<=360,"J+6",IF(D23*1440<=480,"J+8","8以上"))))))
D24: =IF(OR(B24="",C24=""),"",ROUND((IF(C24<1,INT(B24)+C24,C24)-B24)*1440,0)/1440) | E24: =IF(D24="","",IF(D24<0,"打日期",IF(D24*1440<=120,"J+2",IF(D24*1440<=240,"J+4",IF(D24*1440<=360,"J+6",IF(D24*1440<=480,"J+8","8以上"))))))
D25: =IF(OR(B25="",C25=""),"",ROUND((IF(C25<1,INT(B25)+C25,C25)-B25)*1440,0)/1440) | E25: =IF(D25="","",IF(D25<0,"打日期",IF(D25*1440<=120,"J+2",IF(D25*1440<=240,"J+4",IF(D25*1440<=360,"J+6",IF(D25*1440<=480,"J+8","8以上"))))))
D26: =IF(OR(B26="",C26=""),"",ROUND((IF(C26<1,INT(B26)+C26,C26)-B26)*1440,0)/1440) | E26: =IF(D26="","",IF(D26<0,"打日期",IF(D26*1440<=120,"J+2",IF(D26*1440<=240,"J+4",IF(D26*1440<=360,"J+6",IF(D26*1440<=480,"J+8","8以上"))))))
D27: =IF(OR(B27="",C27=""),"",ROUND((IF(C27<1,INT(B27)+C27,C27)-B27)*1440,0)/1440) | E27: =IF(D27="","",IF(D27<0,"打日期",IF(D27*1440<=120,"J+2",IF(D27*1440<=240,"J+4",IF(D27*1440<=360,"J+6",IF(D27*1440<=480,"J+8","8以上"))))))
D28: =IF(OR(B28="",C28=""),"",ROUND((IF(C28<1,INT(B28)+C28,C28)-B28)*1440,0)/1440) | E28: =IF(D28="","",IF(D28<0,"打日期",IF(D28*1440<=120,"J+2",IF(D28*1440<=240,"J+4",IF(D28*1440<=360,"J+6",IF(D28*1440<=480,"J+8","8以上"))))))
D29: =IF(OR(B29="",C29=""),"",ROUND((IF(C29<1,INT(B29)+C29,C29)-B29)*1440,0)/1440) | E29: =IF(D29="","",IF(D29<0,"打日期",IF(D29*1440<=120,"J+2",IF(D29*1440<=240,"J+4",IF(D29*1440<=360,"J+6",IF(D29*1440<=480,"J+8","8以上"))))))
D30: =IF(OR(B30="",C30=""),"",ROUND((IF(C30<1,INT(B30)+C30,C30)-B30)*1440,0)/1440) | E30: =IF(D30="","",IF(D30<0,"打日期",IF(D30*1440<=120,"J+2",IF(D30*1440<=240,"J+4",IF(D30*1440<=360,"J+6",IF(D30*1440<=480,"J+8","8以上"))))))
D31: =IF(OR(B31="",C31=""),"",ROUND((IF(C31<1,INT(B31)+C31,C31)-B31)*1440,0)/1440) | E31: =IF(D31="","",IF(D31<0,"打日期",IF(D31*1440<=120,"J+2",IF(D31*1440<=240,"J+4",IF(D31*1440<=360,"J+6",IF(D31*1440<=480,"J+8","8以上"))))))
D32: =IF(OR(B32="",C32=""),"",ROUND((IF(C32<1,INT(B32)+C32,C32)-B32)*1440,0)/1440) | E32: =IF(D32="","",IF(D32<0,"打日期",IF(D32*1440<=120,"J+2",IF(D32*1440<=240,"J+4",IF(D32*1440<=360,"J+6",IF(D32*1440<=480,"J+8","8以上"))))))
D33: =IF(OR(B33="",C33=""),"",ROUND((IF(C33<1,INT(B33)+C33,C33)-B33)*1440,0)/1440) | E33: =IF(D33="","",IF(D33<0,"打日期",IF(D33*1440<=120,"J+2",IF(D33*1440<=240,"J+4",IF(D33*1440<=360,"J+6",IF(D33*1440<=480,"J+8","8以上"))))))
D34: =IF(OR(B34="",C34=""),"",ROUND((IF(C34<1,INT(B34)+C34,C34)-B34)*1440,0)/1440) | E34: =IF(D34="","",IF(D34<0,"打日期",IF(D34*1440<=120,"J+2",IF(D34*1440<=240,"J+4",IF(D34*1440<=360,"J+6",IF(D34*1440<=480,"J+8","8以上"))))))
... D37: =IF(OR(B37="",C37=""),"",ROUND((IF(C37<1,INT(B37)+C37,C37)-B37)*1440,0)/1440) | E37: =IF(D37="","",IF(D37<0,"打日期",IF(D37*1440<=120,"J+2",IF(D37*1440<=240,"J+4",IF(D37*1440<=360,"J+6",IF(D37*1440<=480,"J+8","8以上"))))))
A38: 十大都市:( 11時前交寄之郵件) 台北市(100-110)、基隆市(200~206)、桃園市(330)、中壢市(含平鎮，320、324)、台中市(400-408)、彰化市(500)、嘉義市(600)、台南市(700-709)、高雄市(800-804、806、807)互寄者。
A40: 製表: | C40: 主管:
A41: ="中和郵務股"&'05'!$G$2&'05'!$H$2&"份 區域內互寄 快捷郵遞時效表" -> 中和郵務股115年5月份 區域內互寄 快捷郵遞時效表
A42: 郵件號碼 | B42: 交寄時間 | C42: 交投時間 | D42: 時數 | E42: 時效
D43: =IF(OR(B43="",C43=""),"",ROUND((IF(C43<1,INT(B43)+C43,C43)-B43)*1440,0)/1440) | E43: =IF(D43="","",IF(D43<0,"打日期",IF(D43*1440<=120,"J+2",IF(D43*1440<=240,"J+4",IF(D43*1440<=360,"J+6",IF(D43*1440<=480,"J+8","8以上"))))))
D44: =IF(OR(B44="",C44=""),"",ROUND((IF(C44<1,INT(B44)+C44,C44)-B44)*1440,0)/1440) | E44: =IF(D44="","",IF(D44<0,"打日期",IF(D44*1440<=120,"J+2",IF(D44*1440<=240,"J+4",IF(D44*1440<=360,"J+6",IF(D44*1440<=480,"J+8","8以上"))))))
D45: =IF(OR(B45="",C45=""),"",ROUND((IF(C45<1,INT(B45)+C45,C45)-B45)*1440,0)/1440) | E45: =IF(D45="","",IF(D45<0,"打日期",IF(D45*1440<=120,"J+2",IF(D45*1440<=240,"J+4",IF(D45*1440<=360,"J+6",IF(D45*1440<=480,"J+8","8以上"))))))
D46: =IF(OR(B46="",C46=""),"",ROUND((IF(C46<1,INT(B46)+C46,C46)-B46)*1440,0)/1440) | E46: =IF(D46="","",IF(D46<0,"打日期",IF(D46*1440<=120,"J+2",IF(D46*1440<=240,"J+4",IF(D46*1440<=360,"J+6",IF(D46*1440<=480,"J+8","8以上"))))))
...

Sheet 06
A1: 中和郵局 抽測國內快捷情形報告單
G2: ='01'!G2 -> 115年 | H2: 6月
A3: 互寄地區 | C3: 抽測件數 | D3: J+2時 件數 | E3: J+2時 投遞率 | F3: J+4時 件數 | G3: J+4時 投遞率 | H3: J+6時 件數 | I3: J+6時 投遞率 | J3: J+8時 件數 | K3: J+8時 投遞率 | L3: 8時以上 件數 | M3: 8時以上 投遞率 | N3: 符合時效比例 | O3: 平均 (時)數
A4: 本收本投 | C4: =D4+F4+H4+J4+L4 -> 0 | D4: =COUNTIF(06子本!$E$3:$E$17,"J+2") -> 0 | E4: =IF($C4=0,"",D4/$C4) | F4: =COUNTIF(06子本!$E$3:$E$17,"J+4") -> 0 | G4: =IF($C4=0,"",F4/$C4) | H4: =COUNTIF(06子本!$E$3:$E$17,"J+6") -> 0 | I4: =IF($C4=0,"",H4/$C4) | J4: =COUNTIF(06子本!$E$3:$E$17,"J+8") -> 0 | K4: =IF($C4=0,"",J4/$C4) | L4: =COUNTIF(06子本!$E$3:$E$17,"8以上") -> 0 | M4: =IF($C4=0,"",L4/$C4) | N4: 1 | O4: =IF($C4=0,"",(D4*2+F4*4+H4*6+J4*8+L4*8)/$C4)
A5: 主要都市間互寄 | C5: =D5+F5+H5+J5+L5 -> 0 | D5: =COUNTIF(06子本!$E$23:$E$37,"J+2") -> 0 | E5: =IF($C5=0,"",D5/$C5) | F5: =COUNTIF(06子本!$E$23:$E$37,"J+4") -> 0 | G5: =IF($C5=0,"",F5/$C5) | H5: =COUNTIF(06子本!$E$23:$E$37,"J+6") -> 0 | I5: =IF($C5=0,"",H5/$C5) | J5: =COUNTIF(06子本!$E$23:$E$37,"J+8") -> 0 | K5: =IF($C5=0,"",J5/$C5) | L5: =COUNTIF(06子本!$E$23:$E$37,"8以上") -> 0 | M5: =IF($C5=0,"",L5/$C5) | N5: 1 | O5: =IF($C5=0,"",(D5*2+F5*4+H5*6+J5*8+L5*8)/$C5)
A6: 區域內互寄 (北北基、台中、高雄、中彰投地區) | C6: =D6+F6+H6+J6+L6 -> 0 | D6: =COUNTIF(06子本!$E$43:$E$57,"J+2") -> 0 | E6: =IF($C6=0,"",D6/$C6) | F6: =COUNTIF(06子本!$E$43:$E$57,"J+4") -> 0 | G6: =IF($C6=0,"",F6/$C6) | H6: =COUNTIF(06子本!$E$43:$E$57,"J+6") -> 0 | I6: =IF($C6=0,"",H6/$C6) | J6: =COUNTIF(06子本!$E$43:$E$57,"J+8") -> 0 | K6: =IF($C6=0,"",J6/$C6) | L6: =COUNTIF(06子本!$E$43:$E$57,"8以上") -> 0 | M6: =IF($C6=0,"",L6/$C6) | N6: 1 | O6: =IF($C6=0,"",(D6*2+F6*4+H6*6+J6*8+L6*8)/$C6)
A7: 其他轉口 | C7: =D7+F7+H7+J7+L7 -> 0 | D7: =COUNTIF(06子本!$E$63:$E$77,"J+2") -> 0 | E7: =IF($C7=0,"",D7/$C7) | F7: =COUNTIF(06子本!$E$63:$E$77,"J+4") -> 0 | G7: =IF($C7=0,"",F7/$C7) | H7: =COUNTIF(06子本!$E$63:$E$77,"J+6") -> 0 | I7: =IF($C7=0,"",H7/$C7) | J7: =COUNTIF(06子本!$E$63:$E$77,"J+8") -> 0 | K7: =IF($C7=0,"",J7/$C7) | L7: =COUNTIF(06子本!$E$63:$E$77,"8以上") -> 0 | M7: =IF($C7=0,"",L7/$C7) | N7: 1 | O7: =IF($C7=0,"",(D7*2+F7*4+H7*6+J7*8+L7*8)/$C7)
A8: 說明：
A9: 1 | B9: 為瞭解國內快捷郵件寄遞時效，各局快捷單位應透過MQ或本公司全球資訊網查詢系統抽測「本收本投」、「主要都市互寄」、「區域內互寄」、「其他轉口」4類，每月至少各10件（抽查紀錄列印或記錄郵件號碼留局備查，保存1年），抽測結果於次月5日前寄管轄郵局郵務科彙整，於8日前上傳主機。
A10: 2 | B10: 抽測樣本：本收本投以15時前交寄、主要都市互寄11時前交寄、區域間互寄13時前交寄之郵件抽測為主。
A11: 3 | B11: 寄遞時效：自「交寄郵件」到「郵件投遞中」之處理狀態時間計算，四小時以內者填「ｊ＋4時」欄；逾四小時不逾六小時者填「ｊ＋6時」欄，餘類推。抽測結果有不符合時效標準者，請將相關地名列出，並檢討改善。
A12: 4 | B12: 十大都市互寄係指台北市(100-110)、板橋市(220)、桃園市(330)、中壢市(含平鎮，320、324)、新竹市(300)、台中市(400-408)、彰化市(500)、嘉義市(600)、台南市(700-709)、高雄市(800-804、806、807)互寄者。該欄位僅由該十大都市互寄局就相關之郵件抽測情形填註。
A13: 5 | B13: 平均(時)數：((J+2小時投遞率)*2+(J+4小時投遞率)*4+(J+6小時投遞率)*6+(J+8小時投遞率)*8+(J+8小時以上投遞率)*8)/100。
B14: 製表: | F14: 主管:

Sheet 06子本
A1: ="中和郵務股"&'06'!$G$2&'06'!$H$2&"份 本口 快捷郵遞時效表" -> 中和郵務股115年6月份 本口 快捷郵遞時效表
A2: 郵件號碼 | B2: 交寄時間 | C2: 交投時間 | D2: 時數 | E2: 時效
D3: =IF(OR(B3="",C3=""),"",ROUND((IF(C3<1,INT(B3)+C3,C3)-B3)*1440,0)/1440) | E3: =IF(D3="","",IF(D3<0,"打日期",IF(D3*1440<=120,"J+2",IF(D3*1440<=240,"J+4",IF(D3*1440<=360,"J+6",IF(D3*1440<=480,"J+8","8以上"))))))
D4: =IF(OR(B4="",C4=""),"",ROUND((IF(C4<1,INT(B4)+C4,C4)-B4)*1440,0)/1440) | E4: =IF(D4="","",IF(D4<0,"打日期",IF(D4*1440<=120,"J+2",IF(D4*1440<=240,"J+4",IF(D4*1440<=360,"J+6",IF(D4*1440<=480,"J+8","8以上"))))))
D5: =IF(OR(B5="",C5=""),"",ROUND((IF(C5<1,INT(B5)+C5,C5)-B5)*1440,0)/1440) | E5: =IF(D5="","",IF(D5<0,"打日期",IF(D5*1440<=120,"J+2",IF(D5*1440<=240,"J+4",IF(D5*1440<=360,"J+6",IF(D5*1440<=480,"J+8","8以上"))))))
D6: =IF(OR(B6="",C6=""),"",ROUND((IF(C6<1,INT(B6)+C6,C6)-B6)*1440,0)/1440) | E6: =IF(D6="","",IF(D6<0,"打日期",IF(D6*1440<=120,"J+2",IF(D6*1440<=240,"J+4",IF(D6*1440<=360,"J+6",IF(D6*1440<=480,"J+8","8以上"))))))
D7: =IF(OR(B7="",C7=""),"",ROUND((IF(C7<1,INT(B7)+C7,C7)-B7)*1440,0)/1440) | E7: =IF(D7="","",IF(D7<0,"打日期",IF(D7*1440<=120,"J+2",IF(D7*1440<=240,"J+4",IF(D7*1440<=360,"J+6",IF(D7*1440<=480,"J+8","8以上"))))))
D8: =IF(OR(B8="",C8=""),"",ROUND((IF(C8<1,INT(B8)+C8,C8)-B8)*1440,0)/1440) | E8: =IF(D8="","",IF(D8<0,"打日期",IF(D8*1440<=120,"J+2",IF(D8*1440<=240,"J+4",IF(D8*1440<=360,"J+6",IF(D8*1440<=480,"J+8","8以上"))))))
D9: =IF(OR(B9="",C9=""),"",ROUND((IF(C9<1,INT(B9)+C9,C9)-B9)*1440,0)/1440) | E9: =IF(D9="","",IF(D9<0,"打日期",IF(D9*1440<=120,"J+2",IF(D9*1440<=240,"J+4",IF(D9*1440<=360,"J+6",IF(D9*1440<=480,"J+8","8以上"))))))
D10: =IF(OR(B10="",C10=""),"",ROUND((IF(C10<1,INT(B10)+C10,C10)-B10)*1440,0)/1440) | E10: =IF(D10="","",IF(D10<0,"打日期",IF(D10*1440<=120,"J+2",IF(D10*1440<=240,"J+4",IF(D10*1440<=360,"J+6",IF(D10*1440<=480,"J+8","8以上"))))))
D11: =IF(OR(B11="",C11=""),"",ROUND((IF(C11<1,INT(B11)+C11,C11)-B11)*1440,0)/1440) | E11: =IF(D11="","",IF(D11<0,"打日期",IF(D11*1440<=120,"J+2",IF(D11*1440<=240,"J+4",IF(D11*1440<=360,"J+6",IF(D11*1440<=480,"J+8","8以上"))))))
D12: =IF(OR(B12="",C12=""),"",ROUND((IF(C12<1,INT(B12)+C12,C12)-B12)*1440,0)/1440) | E12: =IF(D12="","",IF(D12<0,"打日期",IF(D12*1440<=120,"J+2",IF(D12*1440<=240,"J+4",IF(D12*1440<=360,"J+6",IF(D12*1440<=480,"J+8","8以上"))))))
D13: =IF(OR(B13="",C13=""),"",ROUND((IF(C13<1,INT(B13)+C13,C13)-B13)*1440,0)/1440) | E13: =IF(D13="","",IF(D13<0,"打日期",IF(D13*1440<=120,"J+2",IF(D13*1440<=240,"J+4",IF(D13*1440<=360,"J+6",IF(D13*1440<=480,"J+8","8以上"))))))
D14: =IF(OR(B14="",C14=""),"",ROUND((IF(C14<1,INT(B14)+C14,C14)-B14)*1440,0)/1440) | E14: =IF(D14="","",IF(D14<0,"打日期",IF(D14*1440<=120,"J+2",IF(D14*1440<=240,"J+4",IF(D14*1440<=360,"J+6",IF(D14*1440<=480,"J+8","8以上"))))))
... D17: =IF(OR(B17="",C17=""),"",ROUND((IF(C17<1,INT(B17)+C17,C17)-B17)*1440,0)/1440) | E17: =IF(D17="","",IF(D17<0,"打日期",IF(D17*1440<=120,"J+2",IF(D17*1440<=240,"J+4",IF(D17*1440<=360,"J+6",IF(D17*1440<=480,"J+8","8以上"))))))
A18: 本地互寄:( 15時前交寄之郵件) 板橋市22071~81、92
A20: 製表: | C20: 主管:
A21: ="中和郵務股"&'06'!$G$2&'06'!$H$2&"份 十大都會區 快捷郵遞時效表" -> 中和郵務股115年6月份 十大都會區 快捷郵遞時效表
A22: 郵件號碼 | B22: 交寄時間 | C22: 交投時間 | D22: 時數 | E22: 時效
D23: =IF(OR(B23="",C23=""),"",ROUND((IF(C23<1,INT(B23)+C23,C23)-B23)*1440,0)/1440) | E23: =IF(D23="","",IF(D23<0,"打日期",IF(D23*1440<=120,"J+2",IF(D23*1440<=240,"J+4",IF(D23*1440<=360,"J+6",IF(D23*1440<=480,"J+8","8以上"))))))
D24: =IF(OR(B24="",C24=""),"",ROUND((IF(C24<1,INT(B24)+C24,C24)-B24)*1440,0)/1440) | E24: =IF(D24="","",IF(D24<0,"打日期",IF(D24*1440<=120,"J+2",IF(D24*1440<=240,"J+4",IF(D24*1440<=360,"J+6",IF(D24*1440<=480,"J+8","8以上"))))))
D25: =IF(OR(B25="",C25=""),"",ROUND((IF(C25<1,INT(B25)+C25,C25)-B25)*1440,0)/1440) | E25: =IF(D25="","",IF(D25<0,"打日期",IF(D25*1440<=120,"J+2",IF(D25*1440<=240,"J+4",IF(D25*1440<=360,"J+6",IF(D25*1440<=480,"J+8","8以上"))))))
D26: =IF(OR(B26="",C26=""),"",ROUND((IF(C26<1,INT(B26)+C26,C26)-B26)*1440,0)/1440) | E26: =IF(D26="","",IF(D26<0,"打日期",IF(D26*1440<=120,"J+2",IF(D26*1440<=240,"J+4",IF(D26*1440<=360,"J+6",IF(D26*1440<=480,"J+8","8以上"))))))
D27: =IF(OR(B27="",C27=""),"",ROUND((IF(C27<1,INT(B27)+C27,C27)-B27)*1440,0)/1440) | E27: =IF(D27="","",IF(D27<0,"打日期",IF(D27*1440<=120,"J+2",IF(D27*1440<=240,"J+4",IF(D27*1440<=360,"J+6",IF(D27*1440<=480,"J+8","8以上"))))))
D28: =IF(OR(B28="",C28=""),"",ROUND((IF(C28<1,INT(B28)+C28,C28)-B28)*1440,0)/1440) | E28: =IF(D28="","",IF(D28<0,"打日期",IF(D28*1440<=120,"J+2",IF(D28*1440<=240,"J+4",IF(D28*1440<=360,"J+6",IF(D28*1440<=480,"J+8","8以上"))))))
D29: =IF(OR(B29="",C29=""),"",ROUND((IF(C29<1,INT(B29)+C29,C29)-B29)*1440,0)/1440) | E29: =IF(D29="","",IF(D29<0,"打日期",IF(D29*1440<=120,"J+2",IF(D29*1440<=240,"J+4",IF(D29*1440<=360,"J+6",IF(D29*1440<=480,"J+8","8以上"))))))
D30: =IF(OR(B30="",C30=""),"",ROUND((IF(C30<1,INT(B30)+C30,C30)-B30)*1440,0)/1440) | E30: =IF(D30="","",IF(D30<0,"打日期",IF(D30*1440<=120,"J+2",IF(D30*1440<=240,"J+4",IF(D30*1440<=360,"J+6",IF(D30*1440<=480,"J+8","8以上"))))))
D31: =IF(OR(B31="",C31=""),"",ROUND((IF(C31<1,INT(B31)+C31,C31)-B31)*1440,0)/1440) | E31: =IF(D31="","",IF(D31<0,"打日期",IF(D31*1440<=120,"J+2",IF(D31*1440<=240,"J+4",IF(D31*1440<=360,"J+6",IF(D31*1440<=480,"J+8","8以上"))))))
D32: =IF(OR(B32="",C32=""),"",ROUND((IF(C32<1,INT(B32)+C32,C32)-B32)*1440,0)/1440) | E32: =IF(D32="","",IF(D32<0,"打日期",IF(D32*1440<=120,"J+2",IF(D32*1440<=240,"J+4",IF(D32*1440<=360,"J+6",IF(D32*1440<=480,"J+8","8以上"))))))
D33: =IF(OR(B33="",C33=""),"",ROUND((IF(C33<1,INT(B33)+C33,C33)-B33)*1440,0)/1440) | E33: =IF(D33="","",IF(D33<0,"打日期",IF(D33*1440<=120,"J+2",IF(D33*1440<=240,"J+4",IF(D33*1440<=360,"J+6",IF(D33*1440<=480,"J+8","8以上"))))))
D34: =IF(OR(B34="",C34=""),"",ROUND((IF(C34<1,INT(B34)+C34,C34)-B34)*1440,0)/1440) | E34: =IF(D34="","",IF(D34<0,"打日期",IF(D34*1440<=120,"J+2",IF(D34*1440<=240,"J+4",IF(D34*1440<=360,"J+6",IF(D34*1440<=480,"J+8","8以上"))))))
... D37: =IF(OR(B37="",C37=""),"",ROUND((IF(C37<1,INT(B37)+C37,C37)-B37)*1440,0)/1440) | E37: =IF(D37="","",IF(D37<0,"打日期",IF(D37*1440<=120,"J+2",IF(D37*1440<=240,"J+4",IF(D37*1440<=360,"J+6",IF(D37*1440<=480,"J+8","8以上"))))))
A38: 十大都市:( 11時前交寄之郵件) 台北市(100-110)、基隆市(200~206)、桃園市(330)、中壢市(含平鎮，320、324)、台中市(400-408)、彰化市(500)、嘉義市(600)、台南市(700-709)、高雄市(800-804、806、807)互寄者。
A40: 製表: | C40: 主管:
A41: ="中和郵務股"&'06'!$G$2&'06'!$H$2&"份 區域內互寄 快捷郵遞時效表" -> 中和郵務股115年6月份 區域內互寄 快捷郵遞時效表
A42: 郵件號碼 | B42: 交寄時間 | C42: 交投時間 | D42: 時數 | E42: 時效
D43: =IF(OR(B43="",C43=""),"",ROUND((IF(C43<1,INT(B43)+C43,C43)-B43)*1440,0)/1440) | E43: =IF(D43="","",IF(D43<0,"打日期",IF(D43*1440<=120,"J+2",IF(D43*1440<=240,"J+4",IF(D43*1440<=360,"J+6",IF(D43*1440<=480,"J+8","8以上"))))))
D44: =IF(OR(B44="",C44=""),"",ROUND((IF(C44<1,INT(B44)+C44,C44)-B44)*1440,0)/1440) | E44: =IF(D44="","",IF(D44<0,"打日期",IF(D44*1440<=120,"J+2",IF(D44*1440<=240,"J+4",IF(D44*1440<=360,"J+6",IF(D44*1440<=480,"J+8","8以上"))))))
D45: =IF(OR(B45="",C45=""),"",ROUND((IF(C45<1,INT(B45)+C45,C45)-B45)*1440,0)/1440) | E45: =IF(D45="","",IF(D45<0,"打日期",IF(D45*1440<=120,"J+2",IF(D45*1440<=240,"J+4",IF(D45*1440<=360,"J+6",IF(D45*1440<=480,"J+8","8以上"))))))
D46: =IF(OR(B46="",C46=""),"",ROUND((IF(C46<1,INT(B46)+C46,C46)-B46)*1440,0)/1440) | E46: =IF(D46="","",IF(D46<0,"打日期",IF(D46*1440<=120,"J+2",IF(D46*1440<=240,"J+4",IF(D46*1440<=360,"J+6",IF(D46*1440<=480,"J+8","8以上"))))))
...

Sheet 07
A1: 中和郵局 抽測國內快捷情形報告單
G2: ='01'!G2 -> 115年 | H2: 7月
A3: 互寄地區 | C3: 抽測件數 | D3: J+2時 件數 | E3: J+2時 投遞率 | F3: J+4時 件數 | G3: J+4時 投遞率 | H3: J+6時 件數 | I3: J+6時 投遞率 | J3: J+8時 件數 | K3: J+8時 投遞率 | L3: 8時以上 件數 | M3: 8時以上 投遞率 | N3: 符合時效比例 | O3: 平均 (時)數
